Workbook

Sheet Monthly sheet 
B1: AFRICAN GAMESKIN GROUP (PTY) LTD
B2: DATE: March 2026
B4: SALES | G4: PURCHASES | K4: BANK:
B6: TURNOVER | D6: =+'Income Statement '!C4+'Income Statement '!C5 -> 8458767.2 | G6: HANNITAN - RECEIVED IN MONTH | K6: NEDBANK | L6: =+'Balance sheet '!C38 -> 989367.23
B7: TURNOVER - EXPORTS | D7: =+'Income Statement '!C6 -> 337667.32 | G7: =+Hannitan!B39-3771.68 -> 21732.56 | H7: M2 | K7: CFC | L7: =+'Balance sheet '!C39 -> 6759923.4
G8: =+Hannitan!D39-723725.5 -> 4793208.5 | H8: VALUE EXCL VAT
D9: =SUM(D6:D8) -> 8796434.5 | G9: 294343.65 | H9: 5% DISCOUNT
C10: M2 | G10: =+G8-G9 -> 4498864.9 | H10: TOTAL
B11: LEATHER SOLD: | C11: =+'Sales '!B41 -> 24919.38 | D11: =+'Sales '!C41 -> 8193921.2 | G11: =+G10/G7 -> 207.01035 | H11: AVERAGE PRICE | K11: LOAN ACCOUNTS
B12: AVERAGE SELLING PRICE: | C12: =+D11/C11 -> 328.81722
B13: LEATHER PURCHASED: | C13: =+G7+G15 -> 28543.16 | D13: =+G10+G16 -> 6769998.4 | G13: FUSION LEATHER - RECEIVED IN MONTH | K13: Spolden Inv | L13: 0
B14: AVERAGE PURCHASE PRICE : | C14: =D13/C13 -> 237.18462 | K14: Hildene Inv | L14: =+'Balance sheet '!C36 -> 1526847.6
G15: =+FLW!B25 -> 6810.6 | H15: M2 | L15: =SUM(L12:L14) -> 1526847.6
B16: SALES BREAKDOWN | G16: =+FLW!D25 -> 2271133.6 | H16: VALUE EXCL VAT
C17: March'26 | D17: Feb'26 | G17: =+G16/G15 -> 333.47041 | H17: AVERAGE PRICE
K18: INCOME STATEMENT MARCH 2026
B19: Durban Branch | C19: =+'[1]Sales Rep per month'!$C$48 -> 2544.32 | D19: =+'[1]Sales per Branch'!$L$14 -> 2823 | G19: DEBTORS AGING AT END OF THE MONTH: | K19: TURNOVER | L19: =+'Income Statement '!D6 -> 8796434.5
G20: CURRENT | H20: =+'Debtors '!F190 -> 5557631.3 | K20: COST OF SALES | L20: =+'Income Statement '!D10 -> 7443520.5
G21: 30DAYS | H21: =+'Debtors '!E190 -> 3589590.3 | K21: GROSS PROFIT | L21: =+L19-L20 -> 1352914 | M21: =+L21/L19 -> 0.15380254
B22: JHB Branch | C22: =+'[1]Sales Rep per month'!$C$51 -> 10150.71 | D22: 10084.77 | G22: 60DAYS | H22: =+'Debtors '!D190 -> 438208.68 | K22: OTHER INCOME | L22: =+'Income Statement '!D16 -> 803916.31
G23: 90DAYS | H23: =+'Debtors '!C190 -> 221228.3 | K23: EXPENSES | L23: =+'Income Statement '!D42 -> 988310.05 | M23: =L23/L19 -> 0.11235348
G24: 120DAYS | H24: =+'Debtors '!B190 -> 365380.25 | K24: NET PROFIT | L24: =L21+L22-L23 -> 1168520.2 | M24: =+L24/L19 -> 0.13284021
B25: Cape Town Branch | C25: =+'[1]Sales Rep per month'!$C$56 -> 12223.94 | D25: =+'[1]Sales per Branch'!$J$14 -> 17391 | H25: =SUM(H20:H24) -> 10172039
K26: INCOME STATEMENT YTD
B27: Total m2 sold | C27: =SUM(C18:C26) -> 24918.97 | D27: =SUM(D19:D26) -> 30298.77 | G27: CREDITORS AGING: | K27: TURNOVER | L27: =+L19 -> 8796434.5
G28: CURRENT | H28: =+'Suppliers '!H18 -> 1397414.2 | K28: COST OF SALES | L28: =+L20 -> 7443520.5
B29: TOP 10 CUSTOMERS | C29: DM2 | D29: VALUE | G29: 30DAYS | H29: 0 | K29: GROSS PROFIT | L29: =L27-L28 -> 1352914 | M29: =+L29/L27 -> 0.15380254
B30: INS011 - INSPIRE RENTALS PTY LTD | C30: 1873.16 | D30: 468704.8 | G30: 60DAYS | H30: 0 | K30: OTHER INCOME | L30: =+L22 -> 803916.31
B31: BOO002 - BOOT & RALLY (PTY) (LTD) | C31: 1296.13 | D31: 452599.8 | H31: =SUM(H28:H30) -> 1397414.2 | K31: EXPENSES | L31: =+L23 -> 988310.05 | M31: =L31/L27 -> 0.11235348
B32: JUL003 - JULIANA DESIGNS (PTY) LTD | C32: 1198.22 | D32: 317528.3 | K32: NET PROFIT | L32: =L29+L30-L31 -> 1168520.2 | M32: =+L32/L27 -> 0.13284021
B33: AFI001 - AFIKA PROMOTIONS | C33: 747.45 | D33: 313483.95 | G33: STOCK | H33: =+M40 -> 25627566
B34: LEA04 - LEATHER DIRECT (Pty) Ltd | C34: 634.24 | D34: 159416.4 | G34: DEBTORS | H34: =+H25 -> 10172039 | K34: STOCK - March 2026
B35: ALW002 - ALWAYS AROUND (PTY) LTD T/A BEESDAM | C35: 490.61 | D35: 142532.7 | L35: M2 | M35: VALUE
B36: KZN001 - KZN FASTNERS (PTY) LTD | C36: 477.61 | D36: 95044.39 | G36: BANK | H36: =+L7+L6 -> 7749290.6 | K36: Cape Town | L36: =+'[2]Leather Requirements'!$I$112+1330 -> 77489.4 | M36: 20196660
B37: LEA030 - PARIS MANUFACTURING (PTY) LTD | C37: 408.13 | D37: 160883.4 | G37: CREDITORS | H37: =-H31 -> -1397414.2 | K37: JHB | L37: =+'[3]Hides Stock'!$H$105+1136 -> 19734.4 | M37: =+L37*236 -> 4657318.4
B38: GAT003 - GATES 2 AFRICA - MIKE | C38: 398 | D38: 87816.8 | K38: Durban | L38: =3571.5-500 -> 3071.5 | M38: 773587.99
B39: LMA001 - LEATHER MASTER | C39: 359.51 | D39: 104547.7 | K39: Other
G40: TOTAL CURRENT ASSETS: | H40: =SUM(H33:H39) -> 42151482 | L40: TOTAL STOCK: | M40: =SUM(M36:M39) -> 25627566
B41: Top 10 as % of total sales | C41: =+C48 -> 0.31634254
B42: CREDIT NOTES: 119x CREDIT NOTES) | C42: 8% of sales | D42: 673563.19
...

Sheet Sheet1
A1: AFRICAN GAMESKIN GROUP (PTY) LTD | Prepared by: African Gameskin
A2: Sales by Customer Code 01/03/2026 to 31/03/2026
B3: Qty | C3: Total Selling
A4: Customer : KZN001 - KZN FASTNERS (PTY) LTD | B4: 477.61 | C4: 95044.39
A5: Customer : EDD002 - EDDELS SHOES | B5: 158.66 | C5: 69017.1
A6: Customer : JAY001 - JAYS UPHOLSTERS | B6: 101.02 | C6: 23416.8
A7: Customer : HOP001 - HOPEWELL FOOTWEAR | B7: 100.34 | C7: 43273.1
A8: Customer : LUB001 - LUBAN FURNITURE CC | B8: 99.9 | C8: 37238.75
A9: Customer : COS001 - TH STEVENS T/A COSY COUCH | B9: 90.09 | C9: 33030.85
A10: Customer : BEN005 - BENZE UPHOLSTERY | B10: 85.45 | C10: 30272.7
A11: Customer : STR006 - STRAYZ | B11: 76.91 | C11: 28359.9
A12: Customer : HOF002 - HOFFMANN FURNITURE | B12: 73.93 | C12: 16264.6
A13: Customer : BRE003 - BRESAN FOOTWEAR (PTY) LTD | B13: 72.09 | C13: 37185.25
A14: Customer : COR004 - CORVARI FOOTWEAR CC | B14: 71.21 | C14: 24958.7
A15: Customer : CAR029 - CAR & COUCH - MT EDGECOMBE | B15: 60.8 | C15: 16828.4
... A86: GRAND TOTAL | B86: 2550.47 | C86: 869134.88

Sheet Sheet2
A1: AFRICAN GAMESKIN GROUP (PTY) LTD | Prepared by: African Gameskin
A2: Sales by Customer Code 01/03/2026 to 31/03/2026
B3: Qty | C3: Total Selling
A4: Customer : ABE021 - ABEEZ UPHOLSTERY AND MOTOR TRIMMERS | B4: 7.27 | C4: 2617.2
A5: Customer : ABR005 - ABRAMS LEATHER | B5: 6.78 | C5: 2447.1
A6: Customer : ADA011 - ADASAH ATELIER | B6: 0.89 | C6: 203.81
A7: Customer : AFO002 - AFRO COMFORT | B7: 13.45 | C7: 4869.75
A8: Customer : AJK003 - AJK LEATHERS | B8: 3.82 | C8: 878.6
A9: Customer : ALW002 - ALWAYS AROUND (PTY) LTD T/A BEESDAM | B9: 490.61 | C9: 142532.7
A10: Customer : ALW010 - ALWYN ESTERHUIZEN | B10: 5.7 | C10: 2451
A11: Customer : AMO001 - AMOS JONES LEATHER | B11: 9.47 | C11: 2828.84
A12: Customer : ARC013 - ARCADIA DESIGNZ | B12: 20.81 | C12: 8740.2
A13: Customer : ARM004 - ARMIC DESIGN STUDIO | B13: 9.24 | C13: 3009.6
A14: Customer : ASH004 - ASHOK NARSAI INTERIORS | B14: 139.52 | C14: 33484.8
A15: Customer : ATH002 - A2HR COSMETIC SOLUTIONS (PTY) LTD | B15: 138.47 | C15: 34320.3
... A203: GRAND TOTAL | B203: 11077.41 | C203: 3453651.8

Sheet Balance sheet 
A1: AFRICAN GAMESKIN GROUP (PTY) LTD | Prepared by: African Gameskin
A2: BALANCE SHEET as at 31/03/2026
A4: EQUITY AND LIABILITIES
A5: Capital and Reserves
A7: Share Capital
B8: Members contribution | C8: 100 | D8: 100
A9: Retained Income
B10: Retained Income / (Accumulated Loss) | C10: 33130566
B11: Net Profit/Loss this year | C11: 1168520.2 | D11: 34299086 | E11: 34299186
A13: Minority Interest
A14: Non-current Liabilities
D16: 34299186
A17: Current Liabilities
B18: Nedbank Credit Card | C18: 4029.91
B19: Garage Card - Control Account | C19: 60360.63
B20: Supplier Control Account | C20: 1397414.2
B21: Provision for Future Expenses | C21: 103377.73
B22: Vat / Tax Control Account | C22: 159098.43 | D22: 1724280.9 | E22: 1724280.9
A23: Total Equity and Liabilities | D23: 36023467
A25: ASSETS
A26: Non-current Assets
A28: Fixed Assets
B29: Motor Vehicles - Net Value | C29: 1438086.1
B30: Computer Equipment - Net Value | C30: 36323.03
B31: Furniture & Fittings - Net value | C31: 16195.62 | D31: 1490604.7 | E31: 1490604.7
A32: Current Assets
B33: Inventory
C34: Inventory | D34: 12760584
B35: Staff Loan | C35: 4382.2
B36: Hildene Investments (Pty) Ltd | C36: 1526847.6
B37: Customer Control Account | C37: 9926644
B38: Nedbank Cheque 1036 327663 | C38: 989367.23
B39: USD Account 7095014132 | C39: 6759923.4
B40: Petty cash | C40: 17562.54
B41: Petty Cash | C41: 13160.03
B42: Sundry Customers | C42: 84249
B43: Taxation | C43: 2450142.8 | D43: 34532863 | E43: 34532863
A44: Total Assets | D44: 36023467

Sheet Income Statement 
A1: AFRICAN GAMESKIN GROUP (PTY) LTD | Prepared by: African Gameskin
A2: INCOME STATEMENT : 01/03/2026 to 31/03/2026
A3: SALES
B4: Sales | C4: 8457723.7
B5: Sales - other | C5: 1043.48
B6: Sales zero rated | C6: 337667.32 | D6: 8796434.5
A7: COST OF SALES
B8: Cost of Sales / Purchases | C8: 7267470.8
B9: Clearing and forwarding | C9: 58940.77
B10: Courier & Postage | C10: 117108.99 | D10: 7443520.5
A11: GROSS PROFIT / (LOSS) | C11: 1352914
A12: OTHER INCOME
B13: Discount Received for Cash | C13: 294343.65
B14: Interest Received | C14: 9506.17
B15: Sundry Income | C15: 3293.41
B16: Foreign exchange Gain / Loss | C16: 496773.08 | D16: 803916.31
C17: 2156830.3
A18: EXPENSES
B19: Accounting Fees | C19: 5929
B20: Advertising & Promotions | C20: 4791.67
B21: Bank Charges | C21: 3387.1
B22: Cleaning | C22: 8348.53
B23: Computer Expenses | C23: 16393.78
B24: Consumables | C24: 11758.72
B25: Consulting Fees | C25: 28500
B26: Credit card commission | C26: 14074.82
B27: Discount Allowed for Cash | C27: 1584.43
B28: Electricity & Water | C28: 20916.53
B29: Insurance | C29: 30070.27
B30: Interest Paid | C30: 427.25
... B41: Telephone & Fax | C41: 13503.76
B42: Travel & Accommodation | C42: 49800.7 | D42: 988310.05
A43: NET PROFIT / (LOSS) BEFORE TAX | C43: 1168520.2
A44: TAX
A45: DIVIDENDS
A46: NET PROFIT / (LOSS) | C46: 1168520.2

Sheet Year to date

Sheet Debtors 
A1: AFRICAN GAMESKIN GROUP (PTY) LTD | Prepared by: African Gameskin
A2: Customer Age Analysis for Monthly Customers as at 31/03/2026
A3: Name | B3: 120+ Days | C3: 90 Days | D3: 60 Days | E3: 30 Days | F3: Current | G3: Total Due
A4: AARD01 - AARD BRAND | B4: 0 | C4: 0 | D4: 0 | E4: 0 | F4: 7717.55 | G4: 7717.55
A5: AFI001 - AFIKA PROMOTIONS | B5: 0 | C5: 0 | D5: 0 | E5: 134433.06 | F5: 358395.37 | G5: 492828.43
A6: ALE003 - ALEXIOU LEATHER COUCHES | B6: 0 | C6: 2304.05 | D6: 13760.11 | E6: 77520.47 | F6: 30209 | G6: 123793.63
A7: ALW002 - ALWAYS AROUND (PTY) LTD T/A BEESDAM | B7: 0 | C7: 0 | D7: 0 | E7: 0 | F7: 74257.8 | G7: 74257.8
A8: AMO001 - AMOS JONES LEATHER | B8: 0 | C8: 0 | D8: 0 | E8: 0 | F8: 18.89 | G8: 18.89
A9: ANG002 - ANGEL FOOTWEAR | B9: 0 | C9: 0 | D9: 0 | E9: 15486.13 | F9: 30491.74 | G9: 45977.87
A10: ARR002 - QUIVER TRUST T/A ARROW LEATHER GOODS | B10: 0 | C10: 0 | D10: 0 | E10: 0 | F10: 19504.99 | G10: 19504.99
A11: ATP001 - ATPHOTO PTY LTD | B11: 0 | C11: 0 | D11: 0 | E11: 0 | F11: 168.08 | G11: 168.08
A12: BAR003 - E BARONOS LEATHER MANUFACTURERS CC | B12: 0 | C12: 0 | D12: 0 | E12: 10012.25 | F12: 18377.06 | G12: 28389.31
A13: BAR004 - BARNO (PTY) LTD | B13: 0 | C13: 0 | D13: 0 | E13: 0 | F13: 11436.24 | G13: 11436.24
A14: BEN005 - BENZE UPHOLSTERY | B14: 0 | C14: 0 | D14: 0 | E14: 13006.16 | F14: 34813.61 | G14: 47819.77
A15: BLU004 - AMBI & CO t/a BLUEBERRY BLUSH | B15: 0 | C15: 0 | D15: 0 | E15: 8494.44 | F15: 1790.89 | G15: 10285.33
... A190: Totals : | B190: 365380.25 | C190: 221228.3 | D190: 438208.68 | E190: 3589590.3 | F190: 5557631.3 | G190: 10172039
A191: PERCENTAGE : | B191: 3.59% | C191: 2.17% | D191: 4.31% | E191: 35.29% | F191: 54.64% | G191: 100.00%
A192: GRAND TOTALS : | G192: 10172039

Sheet Suppliers 
A1: AFRICAN GAMESKIN GROUP (PTY) LTD | Prepared by: African Gameskin
A2: Supplier Age Analysis as at 31/03/2026
A3: Name | D3: 120+ Days | E3: 90 Days | F3: 60 Days | G3: 30 Days | H3: Current | I3: Total Due
A4: CEZ001 - CEZ Investements | D4: 0 | E4: 0 | F4: 0 | G4: 0 | H4: -55406.05 | I4: -55406.05
A5: CLO001 - CLOUD LOGISTICS | D5: 0 | E5: 0 | F5: 0 | G5: 0 | H5: 8850.9 | I5: 8850.9
A6: COP001 - COPYWRITE BUSINESS CENTRE CC T/A | D6: 0 | E6: 0 | F6: 0 | G6: 0 | H6: 1155 | I6: 1155
A7: FRE001 - FREIGHTMORE | D7: 0 | E7: 0 | F7: 0 | G7: 0 | H7: 90357.49 | I7: 90357.49
A8: HAN001 - HANNITAN LEATHER CC | D8: 0 | E8: 0 | F8: 0 | G8: 0 | H8: -733058.35 | I8: -733058.35
A9: HIL001 - HILDENE INVESTMENTS | D9: 0 | E9: 0 | F9: 0 | G9: 0 | H9: 12455.25 | I9: 12455.25
A10: HIL002 - HILLSPARK | D10: 0 | E10: 0 | F10: 0 | G10: 0 | H10: -551064.84 | I10: -551064.84
A11: OLI001 - OLIVETTI | D11: 0 | E11: 0 | F11: 0 | G11: 0 | H11: 1186.01 | I11: 1186.01
A12: TAN001 - FUSION LEATHER WORLD | D12: 0 | E12: 0 | F12: 0 | G12: 0 | H12: 2618991 | I12: 2618991
A13: THE005 - THE COURIER GUY | D13: 0 | E13: 0 | F13: 0 | G13: 0 | H13: -8066.22 | I13: -8066.22
A14: TOS001 - TOSHIBA | D14: 0 | E14: 0 | F14: 0 | G14: 0 | H14: 813.34 | I14: 813.34
A15: TSS001 - Technical Support Solutions | D15: 0 | E15: 0 | F15: 0 | G15: 0 | H15: -1999 | I15: -1999
... A18: TOTAL : | D18: 0 | E18: 0 | F18: 0 | G18: 0 | H18: 1397414.2 | I18: 1397414.2
A19: PERCENTAGE : | D19: 0.00% | E19: 0.00% | F19: 0.00% | G19: 0.00% | H19: 100.00% | I19: 100.00%
A20: GRAND TOTAL : | I20: 1397414.2

Sheet Sales 
A1: AFRICAN GAMESKIN GROUP (PTY) LTD | Prepared by: African Gameskin
A2: Sales by Inventory Category 01/03/2026 to 31/03/2026
B3: Qty | C3: Total Selling
A4: Category : 000 - None | B4: 412.43 | C4: 100878.7
A5: Category : 001 - Gazelle | B5: 1435.86 | C5: 515008.5
A6: Category : 002 - Woodland B JHB no print | B6: 1596.48 | C6: 420981.67
A7: Category : 003 - Cape Buffalo | B7: 248.38 | C7: 86917.55
A8: Category : 004 - Classic Collection | B8: 153.66 | C8: 55283
A9: Category : 005 - Nappa Collection | B9: 137.88 | C9: 46447.55
A10: Category : 007 - Santos / Sorrento | B10: 1977.97 | C10: 472946.59
A11: Category : 010 - Cow Suede Splits | B11: 164.33 | C11: 56799.5
A12: Category : 012 - Barcelona | B12: 1368.92 | C12: 575442.05
A13: Category : 013 - Fusion Stock Lot | B13: 558.5 | C13: 196163.56
A14: Category : 015 - Navada | B14: 264.05 | C14: 109261.3
A15: Category : 016 - Nova | B15: 195.65 | C15: 62861.83
... A40: Category : 064 - Berlin | B40: 45.26 | C40: 9957.2
A41: GRAND TOTAL | B41: =SUM(B4:B40) -> 24919.38 | C41: =SUM(C4:C40) -> 8193921.2

Sheet Invoices
A1: AFRICAN GAMESKIN GROUP (PTY) LTD | Prepared by: African Gameskin
A2: Sales Journal for period 01/03/2026 to 31/03/2026
A4: Customer | B4: Document | C4: Date | D4: Order | E4: Exclusive | F4: Tax | G4: Inclusive
A5: UPH012 | B5: Credit Note : CR10355 | C5: 02/03/2026 | D5: INW46796 | E5: -1530 | F5: -229.5 | G5: -1759.5
A6: ASH004 | B6: Credit Note : CR10359 | C6: 03/03/2026 | D6: INW46969 | E6: -33427.2 | F6: -5014.08 | G6: -38441.28
A7: BIA004 | B7: Credit Note : CR10360 | C7: 03/03/2026 | D7: INW43783 | E7: -635.85 | F7: -95.38 | G7: -731.23
A8: SAN006 | B8: Credit Note : CR10361 | C8: 03/03/2026 | D8: INW47028 | E8: -9911 | F8: -1486.65 | G8: -11397.65
A9: NIC005 | B9: Credit Note : CR10362 | C9: 03/03/2026 | D9: INW46775 | E9: -5472.3 | F9: -820.85 | G9: -6293.15
A10: TOP009 | B10: Credit Note : CR10363 | C10: 03/03/2026 | D10: INW46954 | E10: -4185 | F10: -627.75 | G10: -4812.75
A11: VER005 | B11: Credit Note : CR10364 | C11: 03/03/2026 | D11: INW46551 | E11: -5222.65 | F11: -783.4 | G11: -6006.05
A12: UMH001 | B12: Credit Note : CR10365 | C12: 03/03/2026 | D12: INW46762
A13: ATA001 | B13: Credit Note : CR10366 | C13: 03/03/2026 | D13: INW46924 | E13: -1169.6 | F13: -175.44 | G13: -1345.04
A14: GEN001 | B14: Credit Note : CR10367 | C14: 03/03/2026 | D14: INW46546 | E14: -2722.05 | F14: -408.31 | G14: -3130.36
A15: FAT004 | B15: Credit Note : CR10368 | C15: 03/03/2026 | D15: INW46739 | E15: -819 | F15: -122.85 | G15: -941.85
A16: LEG005 | B16: Credit Note : CR10369 | C16: 03/03/2026 | D16: INW46987 | E16: -1740 | F16: -261.01 | G16: -2001.01
A17: TOM003 | B17: Credit Note : CR10370 | C17: 04/03/2026 | D17: INW47056 | E17: -1283.85 | F17: -192.58 | G17: -1476.43
A18: FIO001 | B18: Credit Note : CR10371 | C18: 04/03/2026 | D18: INW46766 | E18: -5514.4 | F18: -827.16 | G18: -6341.56
A19: LEE011 | B19: Credit Note : CR10372 | C19: 04/03/2026 | D19: VARIOUS | E19: -3302 | F19: -495.3 | G19: -3797.3
A20: HIG001 | B20: Credit Note : CR10373 | C20: 04/03/2026 | D20: INW46139 | E20: -6038.5 | F20: -905.78 | G20: -6944.28
A21: VAN020 | B21: Credit Note : CR10374 | C21: 04/03/2026 | D21: INW46836 | E21: -1401.75 | F21: -210.26 | G21: -1612.01
A22: ALE003 | B22: Credit Note : CR10375 | C22: 04/03/2026 | D22: INW46712 | E22: -1664.95 | F22: -249.74 | G22: -1914.69
A23: JUL003 | B23: Credit Note : CR10377 | C23: 04/03/2026 | D23: VARIOUS | E23: -3291.3 | F23: -493.69 | G23: -3784.99
A24: MAZ002 | B24: Credit Note : CR10378 | C24: 04/03/2026 | D24: INW47119 | E24: -3318.9 | F24: -497.84 | G24: -3816.74
... A79: BAR004 | B79: Credit Note : CR10433 | C79: 20/03/2026 | D79: INW47677 | E79: -91.8 | F79: -13.77 | G79: -105.57
A80: STE016 | B80: Credit Note : CR10434 | C80: 20/03/2026 | D80: INW47566
A81: KNA002 | B81: Credit Note : CR10435 | C81: 20/03/2026 | D81: INW44727 | E81: -718.25 | F81: -107.74 | G81: -825.99
A82: LEE001 | B82: Credit Note : CR10436 | C82: 20/03/2026 | D82: INW47610 | E82: -3035.1 | F82: -455.27 | G82: -3490.37
A83: STE016 | B83: Credit Note : CR10437 | C83: 23/03/2026 | D83: INW47566 | E83: -3594.8 | F83: -539.23 | G83: -4134.03
A84: FFUN01 | B84: Credit Note : CR10438 | C84: 23/03/2026 | D84: INW46921 | E84: -2902.5 | F84: -435.38 | G84: -3337.88
A85: ZAP001 | B85: Credit Note : CR10439 | C85: 23/03/2026 | D85: INW47536 | E85: -2770.35 | F85: -415.55 | G85: -3185.9
A86: HAW001 | B86: Credit Note : CR10440 | C86: 23/03/2026 | D86: INW45132 | E86: -4020.5 | F86: -603.08 | G86: -4623.58
A87: LUB001 | B87: Credit Note : CR10441 | C87: 23/03/2026 | D87: VARIOUS | E87: -22752.6 | F87: -3412.89 | G87: -26165.49
A88: BRE003 | B88: Credit Note : CR10442 | C88: 23/03/2026 | D88: INW47850 | E88: -1425 | F88: -213.75 | G88: -1638.75
A89: INS011 | B89: Credit Note : CR10443 | C89: 23/03/2026 | D89: INW47876 | E89: -11560.8 | F89: -1734.12 | G89: -13294.92
A90: LEA03 | B90: Credit Note : CR10444 | C90: 23/03/2026 | D90: INW47835 | E90: -37871.6 | F90: -5680.74 | G90: -43552.34
A91: INS011 | B91: Credit Note : CR10445 | C91: 23/03/2026 | D91: 47880 | E91: -1908.2 | F91: -286.23 | G91: -2194.43
A92: CUR009 | B92: Credit Note : CR10446 | C92: 24/03/2026 | D92: VARIOUS | E92: -28945.6 | F92: -4341.84 | G92: -33287.44
A93: GEN001 | B93: Credit Note : CR10447 | C93: 24/03/2026 | D93: INW46781 | E93: -350 | F93: -52.5 | G93: -402.5
A94: CA001 | B94: Credit Note : CR10448 | C94: 24/03/2026 | D94: INW44756 | E94: -1299.3 | F94: -194.9 | G94: -1494.2
A95: JOU004 | B95: Credit Note : CR10449 | C95: 24/03/2026 | D95: INW47966 | E95: -4487 | F95: -673.05 | G95: -5160.05
...

Sheet Stock 

Sheet Per Customer 
A1: AFRICAN GAMESKIN GROUP (PTY) LTD | Prepared by: African Gameskin
A2: Sales by Customer Code 01/03/2026 to 31/03/2026
B3: Qty | C3: Total Selling
A4: INS011 - INSPIRE RENTALS PTY LTD | B4: 1873.16 | C4: 468704.8
A5: BOO002 - BOOT & RALLY (PTY) (LTD) | B5: 1296.13 | C5: 452599.8
A6: JUL003 - JULIANA DESIGNS (PTY) LTD | B6: 1198.22 | C6: 317528.3
A7: AFI001 - AFIKA PROMOTIONS | B7: 747.45 | C7: 313483.95
A8: LEA04 - LEATHER DIRECT (Pty) Ltd | B8: 634.24 | C8: 159416.4
A9: ALW002 - ALWAYS AROUND (PTY) LTD T/A BEESDAM | B9: 490.61 | C9: 142532.7
A10: KZN001 - KZN FASTNERS (PTY) LTD | B10: 477.61 | C10: 95044.39
A11: LEA030 - PARIS MANUFACTURING (PTY) LTD | B11: 408.13 | C11: 160883.4
A12: GAT003 - GATES 2 AFRICA - MIKE | B12: 398 | C12: 87816.8
A13: LMA001 - LEATHER MASTER | B13: 359.51 | C13: 104547.7
A14: FAT004 - FF CLOTHING GROUP CC | B14: 354.98 | C14: 138893.9
A15: INY011 - INYATHI LOUNGE (PTY) LTD | B15: 340.27 | C15: 93436.6
... A567: GRAND TOTAL | B567: 25527.77 | C567: 8602829.1

Sheet Hannitan
A1: AFRICAN GAMESKIN GROUP (PTY) LTD | Prepared by: African Gameskin
A2: Purchase Items per Supplier : 01/03/2026 to 31/03/2026
B3: Qty | C3: Unit Cost | D3: Total
A4: Supplier : HAN001 - HANNITAN LEATHER CC
A5: Item : ANT002 - ANTIQUE BLACK | B5: 405.12 | C5: 215 | D5: 87100.8
A6: Item : ANT003 - ANTIQUE CHOCOLATE | B6: 623.14 | C6: 215 | D6: 133975.1
A7: Item : ANT004 - ANTIQUE TOBACCO | B7: 404.31 | C7: 215 | D7: 86926.65
A8: Item : BWO001 - WOODLAND B PRINT SPICE | B8: 1296.63 | C8: 192 | D8: 248952.96
A9: Item : CAP001 - CAPRIVI SADDLE | B9: 560.42 | C9: 192 | D9: 107600.64
A10: Item : CAP012 - CAPRIVI BRANDY | B10: 592.55 | C10: 192 | D10: 113769.6
A11: Item : CAS001 - CASTROL TOFFEE | B11: 578.09 | C11: 278 | D11: 160709.02
A12: Item : CAS003 - CASTROL BLACK | B12: 576.3 | C12: 278 | D12: 160211.4
A13: Item : CAS005 - CASTROL DENIM | B13: 289.39 | C13: 278 | D13: 80450.42
A14: Item : CAS006 - CASTROL TOBACCO | B14: 567.28 | C14: 278 | D14: 157703.84
A15: Item : DAY002 - DAYTONA ESPRESSO | B15: 622.58 | C15: 270 | D15: 168096.6
A16: Item : DAY006 - DAYTONA TAN | B16: 630.2 | C16: 270 | D16: 170154
... A38: Item : SOR011 - SORRENTO COFFEE | B38: 383.61 | C38: 165 | D38: 63295.65
A39: Total for Supplier : HAN001 - HANNITAN LEATHER CC | B39: =SUM(B5:B38) -> 25504.24 | D39: =SUM(D5:D38) -> 5516934
A40: GRAND TOTAL
D41: =+D39/B39 -> 216.31439

Sheet FLW
A1: AFRICAN GAMESKIN GROUP (PTY) LTD | Prepared by: African Gameskin
A2: Purchase Items per Supplier : 01/03/2026 to 31/03/2026
B3: Qty | C3: Unit Cost | D3: Total
A4: Supplier : TAN001 - FUSION LEATHER WORLD
A5: Item : CHI001 - CHICAGO GREEN | B5: 310.27 | C5: 345 | D5: 107043.15
A6: Item : CHI002 - CHICAGO TAN | B6: 316.11 | C6: 345 | D6: 109057.95
A7: Item : COW001 - COW SUEDE SPLITS CHOC | B7: 323.64 | C7: 242 | D7: 78320.88
A8: Item : COW002 - COW SUEDE SPLITS BLACK | B8: 264.34 | C8: 242 | D8: 63970.28
A9: Item : ECO006 - ECO BOURBON | B9: 307.21 | C9: 342.60424 | D9: 105251.45
A10: Item : ECO008 - ECO TAN | B10: 294.41 | C10: 333.98169 | D10: 98327.55
A11: Item : FLW001 - Fusion Stock Leather | B11: 5.1 | C11: 365 | D11: 1861.5
A12: Item : SAL007 - SALVADOR DARK CHOC | B12: 598.85 | C12: 344.54479 | D12: 206330.65
A13: Item : SHE006 - SHERATON TOFFEE | B13: 224.77 | C13: 345 | D13: 77545.65
A14: Item : TEX008 - TEXAS CHOC | B14: 319.66 | C14: 345 | D14: 110282.7
A15: Item : TEX016 - TEXAS NAVY | B15: 323.93 | C15: 345 | D15: 111755.85
A16: Item : TEX018 - TEXAS MOSS | B16: 320.77 | C16: 345 | D16: 110665.65
... A24: Item : VEG006 - VEG NATURAL SIDES 2.0/2.2mm | B24: 328.98 | C24: 294.03611 | D24: 96732
A25: Total for Supplier : TAN001 - FUSION LEATHER WORLD | B25: =SUM(B5:B24) -> 6810.6 | D25: =SUM(D5:D24) -> 2271133.6
A26: GRAND TOTAL
D27: =+D25/B25 -> 333.47041

Sheet Customer for the year
