Workbook

Sheet Monthly sheet 
B1: AFRICAN GAMESKIN GROUP (PTY) LTD
B2: DATE: JUNE 2026
B4: SALES | G4: PURCHASES | K4: BANK:
B6: TURNOVER | D6: =+'Income Statement '!C4+'Income Statement '!C5 -> 8846029.9 | G6: HANNITAN - RECEIVED IN MONTH | K6: NEDBANK | L6: =+'Balance sheet '!C39 -> 2256051.8
B7: TURNOVER - EXPORTS | D7: =+'Income Statement '!C6 -> 759904.9 | G7: =+Hannitan!B44 -> 27484.3 | H7: M2 | K7: CFC | L7: =+'Balance sheet '!C40 -> 7388251.2
G8: =+Hannitan!D44 -> 6103468.1 | H8: VALUE EXCL VAT
D9: =SUM(D6:D8) -> 9605934.8 | G9: =+'Income Statement '!C13 -> 296994.04 | H9: 5% DISCOUNT
C10: M2 | G10: =+G8-G9 -> 5806474.1 | H10: TOTAL
B11: LEATHER SOLD: | C11: =+'Sales '!B39 -> 28111.71 | D11: =+'Sales '!C39 -> 9157383.6 | G11: =+G10/G7 -> 211.26512 | H11: AVERAGE PRICE | K11: LOAN ACCOUNTS
B12: AVERAGE SELLING PRICE: | C12: =+D11/C11 -> 325.74979
B13: LEATHER PURCHASED: | C13: =+G7+G15 -> 34761.64 | D13: =+G10+G16 -> 8319792 | G13: FUSION LEATHER - RECEIVED IN MONTH | K13: Spolden Inv | L13: 0
B14: AVERAGE PURCHASE PRICE : | C14: =D13/C13 -> 239.3383 | K14: Hildene Inv | L14: =+'Balance sheet '!C37 -> 1526847.6
G15: =+FLW!B37 -> 7277.34 | H15: M2 | L15: =SUM(L12:L14) -> 1526847.6
B16: SALES BREAKDOWN | G16: =+FLW!D37 -> 2513317.9 | H16: VALUE EXCL VAT
C17: June 2026 | D17: May 2026 | G17: =+G16/G15 -> 345.36217 | H17: AVERAGE PRICE
B18: Durban Branch | C18: =+'[1]Sales per Branch'!$T$6 -> 2362 | D18: 2702 | K18: INCOME STATEMENT JUNE 2026
B19: JHB Branch | C19: =+'[1]Sales per Branch'!$S$6 -> 9987 | D19: 9663 | G19: DEBTORS AGING AT END OF THE MONTH: | K19: TURNOVER | L19: 9592256.5
B20: Cape Town Branch | C20: =+'[1]Sales per Branch'!$R$6 -> 15762 | D20: 14573 | G20: CURRENT | H20: =+'Debtors '!F254 -> 5750509.5 | K20: COST OF SALES | L20: =+'Income Statement '!D10 -> 9049304
G21: 30DAYS | H21: =+'Debtors '!E254 -> 2659650.2 | K21: GROSS PROFIT | L21: =+L19-L20 -> 542952.45 | M21: =+L21/L19 -> 0.056603204
B22: Total m2 sold | C22: =SUM(C18:C21) -> 28111 | D22: =SUM(D18:D20) -> 26938 | G22: 60DAYS | H22: =+'Debtors '!D254 -> 339704.74 | K22: OTHER INCOME | L22: 397357.21
G23: 90DAYS | H23: =+'Debtors '!C254 -> 517460.73 | K23: EXPENSES | L23: 952854.61 | M23: =L23/L19 -> 0.099335814
B24: TOP 10 CUSTOMERS | C24: DM2 | D24: VALUE | G24: 120DAYS | H24: =+'Debtors '!B254 -> 233005.84 | K24: NET PROFIT | L24: =L21+L22-L23 -> -12544.95 | M24: =+L24/L19 -> -0.0013078205
B25: INSPIRE RENTALS PTY LTD | C25: 1648.56 | D25: 400521.1 | H25: =SUM(H20:H24) -> 9500331
B26: GH LEATHERS LTD | C26: 1464.08 | D26: 677878.46 | K26: INCOME STATEMENT YTD
B27: JULIANA DESIGNS (PTY) LTD | C27: 1244.83 | D27: 329879.95 | G27: CREDITORS AGING: | K27: TURNOVER | L27: 35799258
B28: COUCH POTATO | C28: 856.94 | D28: 213084.55 | G28: CURRENT | H28: =+'Suppliers '!G22 -> 3246489.7 | K28: COST OF SALES | L28: =+'Year to date'!D10 -> 32069257
B29: INYATHI LOUNGE (PTY) LTD | C29: 834.04 | D29: 202000.95 | G29: 30DAYS | H29: 0 | K29: GROSS PROFIT | L29: =L27-L28 -> 3730000.5 | M29: =+L29/L27 -> 0.10419212
B30: ALWAYS AROUND (PTY) LTD T/A BEESDAM | C30: 787.17 | D30: 221597.55 | G30: 60DAYS | H30: 0 | K30: OTHER INCOME | L30: 1275686.6
B31: LEATHER DIRECT (Pty) Ltd | C31: 722.42 | D31: 181422 | H31: =SUM(H28:H30) -> 3246489.7 | K31: EXPENSES | L31: 3831402.2 | M31: =L31/L27 -> 0.10702463
B32: ROWDY INTERNATIONAL (Pty) Ltd | C32: 707.48 | D32: 215960.95 | K32: NET PROFIT | L32: =L29+L30-L31 -> 1174284.9 | M32: =+L32/L27 -> 0.032801934
B33: LEATHER DIRECT (Pty) Ltd | C33: 597.6 | D33: 148022.8 | G33: STOCK | H33: =+M40 -> 28252762
B34: FF CLOTHING GROUP CC | C34: 583.21 | D34: 232642.6 | G34: DEBTORS | H34: =+H25 -> 9500331 | K34: STOCK - June 2026
L35: M2 | M35: VALUE
B36: Top 10 as % of total sales | C36: =+C48 -> 0.3360283 | G36: BANK | H36: =+L7+L6 -> 9644303 | K36: Cape Town | L36: =53708+18709 -> 72417 | M36: =13573047+6530769 -> 20103816
B37: CREDIT NOTES: 115 x CREDIT NOTES | C37: 5% of sales | D37: 512349.12 | G37: CREDITORS | H37: =-H31 -> -3246489.7 | K37: JHB | L37: =2632+23332+630 -> 26594 | M37: =920425+5013494+94500 -> 6028419
K38: Durban | L38: 3891.47 | M38: 999058.3
K39: Other | M39: =+[2]Gameskin!$F$53 -> 1121468.6
G40: TOTAL CURRENT ASSETS: | H40: =SUM(H33:H39) -> 44150906 | L40: TOTAL STOCK: | M40: =SUM(M36:M39) -> 28252762
D42: =+D37/D9 -> 0.053336727 | G42: Hannitan over deliveries
G44: Fusion delivered R700k in the last 3 days of the month
...

Sheet Sheet1
A1: Purchase Items per Supplier : 01/06/2026 to 30/06/2026
B2: Qty | C2: Unit Cost | D2: Total
A3: Supplier : HAN001 - HANNITAN LEATHER CC
A4: Item : BWO001 - WOODLAND B PRINT SPICE | B4: 1703.95 | C4: 207 | D4: 352717.65
A5: Item : BWO002 - WOODLAND B PRINT TAN | B5: 2485.45 | C5: 207 | D5: 514488.15
A6: Item : CAP002 - CAPE BUFFALO COPPER | B6: 330.06 | C6: 274 | D6: 90436.44
A7: Item : DAY011 - DAYTONA TOFFEE | B7: 424.17 | C7: 292 | D7: 123857.64
A8: Item : ETO003 - ETOSHA CHESTNUT | B8: 600.25 | C8: 207 | D8: 124251.75
A9: Item : ETO007 - ETOSHA EMERALD | B9: 622.8 | C9: 207 | D9: 128919.6
A10: Item : IMP004 - IMPALA BLACK | B10: 573.96 | C10: 189 | D10: 108478.44
A11: Item : SOR001 - SORRENTO BLACK | B11: 1296.02 | C11: 178 | D11: 230691.56
A12: Item : SOR006 - SORRENTO COTTON WHITE | B12: 963.65 | C12: 178 | D12: 171529.7
A13: Item : SOR008 - SORRENTO CARAMEL | B13: 617.25 | C13: 178 | D13: 109870.5
A14: Item : SOR011 - SORRENTO COFFEE | B14: 1272.14 | C14: 178 | D14: 226440.92
A15: Item : WLS001 - WOODLAND BROWN B | B15: 1183.46 | C15: 207 | D15: 244976.22
... A17: Item : WLS003 - WOODLAND CHARCOAL B | B17: 615.31 | C17: 207 | D17: 127369.17
A18: Total for Supplier : HAN001 - HANNITAN LEATHER CC | B18: 13903.48
A19: GRAND TOTAL | D19: 2805534.8
D20: 201.78652

Sheet Balance sheet 
A1: AFRICAN GAMESKIN GROUP (PTY) LTD | Prepared by: African Gameskin
A2: BALANCE SHEET as at 30/06/2026
A4: EQUITY AND LIABILITIES
A5: Capital and Reserves
A7: Share Capital
B8: Members contribution | C8: 100 | D8: 100
A9: Retained Income
B10: Retained Income / (Accumulated Loss) | C10: 33130566
B11: Net Profit/Loss this year | C11: 1056454.4 | D11: 34187021 | E11: 34187121
A12: Shareholders Loan
B13: D Spolander | C13: -4072.66 | D13: -4072.66
A15: Minority Interest
A16: Non-current Liabilities
D17: -4072.66
D18: 34183048
A19: Current Liabilities
B20: Nedbank Credit Card | C20: 8954.5
B21: Garage Card - Control Account | C21: 55539.53
B22: Supplier Control Account | C22: 3246489.7
B23: Provision for Future Expenses | C23: 99554.51 | D23: 3410538.2 | E23: 3410538.2
A24: Total Equity and Liabilities | D24: 37593586
A26: ASSETS
A27: Non-current Assets
A29: Fixed Assets
B30: Motor Vehicles - Net Value | C30: 1438086.1
B31: Computer Equipment - Net Value | C31: 49169.98
B32: Furniture & Fittings - Net value | C32: 16195.62 | D32: 1503451.7 | E32: 1503451.7
A33: Current Assets
B34: Inventory
C35: Inventory | D35: 12760584
B36: Staff Loan | C36: 26632.2
B37: Hildene Investments (Pty) Ltd | C37: 1526847.6
B38: Customer Control Account | C38: 9499994.2
B39: Nedbank Cheque 1036 327663 | C39: 2256051.8
B40: USD Account 7095014132 | C40: 7388251.2
B41: Petty cash | C41: 8836.34
B42: Petty Cash | C42: 64927.84
B43: Sundry Customers | C43: 79748.41
B44: Taxation | C44: 2450142.8
B45: Vat / Tax Control Account | C45: 28118.29 | D45: 36090134 | E45: 36090134
...

Sheet Income Statement 
A1: AFRICAN GAMESKIN GROUP (PTY) LTD | Prepared by: African Gameskin
A2: INCOME STATEMENT : 01/06/2026 to 30/06/2026
A3: SALES
B4: Sales | C4: 8793187
B5: Sales - other | C5: 52842.93
B6: Sales zero rated | C6: 759904.9 | D6: 9605934.8
A7: COST OF SALES
B8: Cost of Sales / Purchases | C8: 8837529
B9: Clearing and forwarding | C9: 28103.92
B10: Courier & Postage | C10: 183671.1 | D10: 9049304
A11: GROSS PROFIT / (LOSS) | C11: 556630.75
A12: OTHER INCOME
B13: Discount Received for Cash | C13: 296994.04
B14: Interest Received | C14: 12748.33
B15: Sundry Income | C15: 2977.76
B16: Foreign exchange Gain / Loss | C16: -2464.26 | D16: 310255.87
C17: 866886.62
A18: EXPENSES
B19: Accounting Fees | C19: 40125
B20: Advertising & Promotions | C20: 4620
B21: Bank Charges | C21: 2174.49
B22: Cleaning | C22: 4336.58
B23: Computer Expenses | C23: 1050.58
B24: Consumables | C24: 10494.2
B25: Credit card commission | C25: 10081.97
B26: Discount Allowed for Cash | C26: 779.7
B27: Electricity & Water | C27: 21886.74
B28: Insurance | C28: 29383.11
B29: Interest Paid | C29: 463.98
B30: Legal Fees | C30: 400
... B42: Telephone & Fax | C42: 14934.43
B43: Travel & Accommodation | C43: 18404.37 | D43: 997262.04
A44: NET PROFIT / (LOSS) BEFORE TAX | C44: -130375.42
A45: TAX
A46: DIVIDENDS
A47: NET PROFIT / (LOSS) | C47: -130375.42

Sheet Year to date
A1: AFRICAN GAMESKIN GROUP (PTY) LTD | Prepared by: African Gameskin
A2: INCOME STATEMENT : 01/03/2026 to 30/06/2026
A3: SALES
B4: Sales | C4: 34310959
B5: Sales - other | C5: 63941.41
B6: Sales zero rated | C6: 1438036.1 | D6: 35812936
A7: COST OF SALES
B8: Cost of Sales / Purchases | C8: 31231842
B9: Clearing and forwarding | C9: 182677.02
B10: Courier & Postage | C10: 654738.04 | D10: 32069257
A11: GROSS PROFIT / (LOSS) | C11: 3743678.8
A12: OTHER INCOME
B13: Discount Received for Cash | C13: 1039525.7
B14: Interest Received | C14: 40601.38
B15: Sundry Income | C15: 6271.17
B16: Foreign exchange Gain / Loss | C16: 102187 | D16: 1188585.2
C17: 4932264
A18: EXPENSES
B19: Accounting Fees | C19: 46454
B20: Advertising & Promotions | C20: 20245
B21: Bank Charges | C21: 42993.55
B22: Cleaning | C22: 21356.88
B23: Computer Expenses | C23: 9031.12
B24: Consumables | C24: 63147.37
B25: Consulting Fees | C25: 48961.29
B26: Credit card commission | C26: 46797.21
B27: Discount Allowed for Cash | C27: 1122.38
B28: Electricity & Water | C28: 84846.08
B29: Gifts | C29: 9129
B30: Insurance | C30: 113925.59
... B44: Telephone & Fax | C44: 57629.92
B45: Travel & Accommodation | C45: 122315.02 | D45: 3875809.6
A46: NET PROFIT / (LOSS) BEFORE TAX | C46: 1056454.4
A47: TAX
A48: DIVIDENDS
A49: NET PROFIT / (LOSS) | C49: 1056454.4

Sheet Debtors 
A1: AFRICAN GAMESKIN GROUP (PTY) LTD | Prepared by: African Gameskin
A2: Customer Age Analysis for Monthly Customers as at 30/06/2026
A3: Name | B3: 120+ Days | C3: 90 Days | D3: 60 Days | E3: 30 Days | F3: Current | G3: Total Due
A4: ABM002 - ABM UPHOLSTERERS | B4: 0 | C4: 0 | D4: 0 | E4: 0 | F4: -403.65 | G4: -403.65
A5: AFI001 - AFIKA PROMOTIONS | B5: 0 | C5: 282273.87 | D5: 7789.76 | E5: 128276.36 | F5: 211205.73 | G5: 629545.72
A6: AGD001 - A&G DESIGN | B6: 0 | C6: 0 | D6: 0 | E6: 0 | F6: -491.63 | G6: -491.63
A7: ALD003 - ALDORA MANUFACTURES | B7: 0 | C7: 0 | D7: 0 | E7: 0 | F7: 2594.4 | G7: 2594.4
A8: ALE003 - ALEXIOU LEATHER COUCHES | B8: 558.9 | C8: 30209 | D8: 12919.91 | E8: 5986.9 | F8: 25069.02 | G8: 74743.73
A9: ALW002 - ALWAYS AROUND (PTY) LTD T/A BEESDAM | B9: 0 | C9: 0 | D9: 0 | E9: 0 | F9: 162693.95 | G9: 162693.95
A10: ANG002 - ANGEL FOOTWEAR | B10: 0 | C10: 30491.74 | D10: 0 | E10: 0 | F10: 0 | G10: 30491.74
A11: ARL006 - ARLEV INVESTMENTS (PTY) LTD | B11: 0 | C11: 0 | D11: 0 | E11: 0 | F11: 44.91 | G11: 44.91
A12: ARN001 - ARNOLD SHOES | B12: 0 | C12: 0 | D12: 0 | E12: -187.91 | F12: 0 | G12: -187.91
A13: ARR002 - QUIVER TRUST T/A ARROW LEATHER GOODS | B13: 0 | C13: 0 | D13: 0 | E13: 0 | F13: 7769.04 | G13: 7769.04
A14: ASC001 - ASCOT UPHOLSTERY | B14: -2558 | C14: 0 | D14: 0 | E14: 0 | F14: 0 | G14: -2558
A15: BAO002 - BAO-BAGS | B15: 0 | C15: 0 | D15: 0 | E15: 0 | F15: 5083.34 | G15: 5083.34
... A254: Totals : | B254: 233005.84 | C254: 517460.73 | D254: 339704.74 | E254: 2659650.2 | F254: 5750509.5 | G254: 9500331
A255: PERCENTAGE : | B255: 2.45% | C255: 5.45% | D255: 3.58% | E255: 28.00% | F255: 60.53% | G255: 100.00%
A256: GRAND TOTALS : | G256: 9500331

Sheet Suppliers 
A1: AFRICAN GAMESKIN GROUP (PTY) LTD | Prepared by: African Gameskin
A2: Supplier Age Analysis as at 30/06/2026
A3: Name | B3: 120+ Days | C3: 90 Days | D3: 60 Days | E3: 30 Days | F3: Current | G3: Total Due
A4: C2M001 - C2M | B4: 0 | C4: 0 | D4: 0 | E4: 460 | F4: 46143.75 | G4: 46603.75
A5: CEZ001 - CEZ Investements | B5: 0 | C5: 0 | D5: 0 | E5: 0 | F5: -56198.37 | G5: -56198.37
A6: CIT002 - CITI - SPRINT EXPRESS COURIER | B6: 0 | C6: 0 | D6: 0 | E6: 0 | F6: 954.87 | G6: 954.87
A7: CLO001 - CLOUD LOGISTICS | B7: 0 | C7: 0 | D7: 0 | E7: 0 | F7: 32227.73 | G7: 32227.73
A8: COP001 - COPYWRITE BUSINESS CENTRE CC T/A | B8: 0 | C8: 0 | D8: 0 | E8: 0 | F8: 4403 | G8: 4403
A9: DPD001 - DPD LOGISTICS | B9: 0 | C9: 0 | D9: 0 | E9: 0 | F9: 12252.61 | G9: 12252.61
A10: FRE001 - FREIGHTMORE | B10: 0 | C10: 0 | D10: 0 | E10: 0 | F10: 127619.78 | G10: 127619.78
A11: HAN001 - HANNITAN LEATHER CC | B11: 0 | C11: 0 | D11: 0 | E11: 0 | F11: 55848.07 | G11: 55848.07
A12: HIL001 - HILDENE INVESTMENTS | B12: 0 | C12: 0 | D12: 0 | E12: 0 | F12: 11034.65 | G12: 11034.65
A13: OLI001 - OLIVETTI | B13: 0 | C13: 0 | D13: 0 | E13: 0 | F13: 1172.35 | G13: 1172.35
A14: SIY002 - SIYA BONGA | B14: 0 | C14: 0 | D14: 0 | E14: 0 | F14: 8330 | G14: 8330
A15: STE002 - STEINER HYGIENE | B15: 0 | C15: 0 | D15: 0 | E15: 0 | F15: -1.6 | G15: -1.6
... A22: TOTAL : | B22: 0 | C22: 0 | D22: 0 | E22: 460 | F22: 3246029.7 | G22: 3246489.7
A23: PERCENTAGE : | B23: 0.00% | C23: 0.00% | D23: 0.00% | E23: 0.01% | F23: 99.99% | G23: 100.00%
A24: GRAND TOTAL : | G24: 3246489.7

Sheet Sales 
A1: AFRICAN GAMESKIN GROUP (PTY) LTD | Prepared by: African Gameskin
A2: Sales by Inventory Category 01/06/2026 to 30/06/2026
B3: Qty | C3: Total Selling
A4: Category : 000 - None | B4: 299.99 | C4: 73439.4
A5: Category : 001 - Gazelle | B5: 1213.13 | C5: 435357.8
A6: Category : 002 - Woodland B JHB no print | B6: 2059.11 | C6: 534706.65
A7: Category : 003 - Cape Buffalo | B7: 179.29 | C7: 62956.45
A8: Category : 004 - Classic Collection | B8: 93.23 | C8: 33935.8
A9: Category : 005 - Nappa Collection | B9: 178.3 | C9: 62895.7
A10: Category : 007 - Santos / Sorrento | B10: 2215.51 | C10: 561768.82
A11: Category : 010 - Cow Suede Splits | B11: 433.61 | C11: 148790
A12: Category : 012 - Barcelona | B12: 1676.45 | C12: 702536.7
A13: Category : 013 - Fusion Stock Lot | B13: 506.46 | C13: 162766.75
A14: Category : 015 - Navada | B14: 42.22 | C14: 25263.5
A15: Category : 016 - Nova | B15: 172.06 | C15: 58545.3
... A38: Category : 051 - Antique | B38: 573.58 | C38: 149130.8
B39: =SUM(B4:B38) -> 28111.71 | C39: =SUM(C4:C38) -> 9157383.6
A40: Category : 057 - XX Skins - Zebra | B40: 1 | C40: 14000
A41: Category : 058 - XX - Skins - Cow hides | B41: 46.26 | C41: 140155
A42: Category : 059 - XX - Skins - Gameskin | B42: 480 | C42: 199366.4
A43: Category : 062 - XX - Transport | B43: 371.92 | C43: 44120.38
A44: Category : 067 - AGS Stock lot | B44: 2 | C44: 0
A45: GRAND TOTAL | B45: 29012.89 | C45: 9555025.4
C50: =+C39-'[1]Sales per month'!$D$73 -> -0.64
C51: 2066302.8

Sheet Invoices
A1: AFRICAN GAMESKIN GROUP (PTY) LTD | Prepared by: African Gameskin
A2: Sales Journal for period 01/06/2026 to 30/06/2026
A4: Customer | B4: Document | C4: Date | D4: Order | E4: Exclusive | F4: Tax | G4: Inclusive
A5: CANCEL | B5: Tax Invoice : 1 | C5: 15/06/2026
A6: CANCEL | B6: Tax Invoice : 2 | C6: 15/06/2026
A7: CANCEL | B7: Tax Invoice : 7 | C7: 15/06/2026
A8: OGU001 | B8: Credit Note : CR10683 | C8: 01/06/2026 | D8: INW50920 | E8: -3160 | F8: -474 | G8: -3634
A9: RUS003 | B9: Credit Note : CR10684 | C9: 01/06/2026 | D9: INW50981 | E9: -777.6 | F9: -116.64 | G9: -894.24
A10: WUN001 | B10: Credit Note : CR10686 | C10: 01/06/2026 | D10: VARIOUS | E10: -17656.4 | F10: -2648.46 | G10: -20304.86
A11: COV021 | B11: Credit Note : CR10690 | C11: 01/06/2026 | D11: INW50828 | E11: -1082.65 | F11: -162.4 | G11: -1245.05
A12: CAM003 | B12: Credit Note : CR10691 | C12: 01/06/2026 | D12: INW50294 | E12: -3404.25 | F12: -510.64 | G12: -3914.89
A13: OKH001 | B13: Credit Note : CR10692 | C13: 02/06/2026 | D13: INW51043 | E13: -2455.2 | F13: -368.28 | G13: -2823.48
A14: VIN006 | B14: Credit Note : CR10693 | C14: 02/06/2026 | D14: INW50765 | E14: -1718.2 | F14: -257.73 | G14: -1975.93
A15: NRH01 | B15: Credit Note : CR10694 | C15: 03/06/2026 | D15: INW50371 | E15: -3266.75 | F15: -490.01 | G15: -3756.76
A16: JUL003 | B16: Credit Note : CR10695 | C16: 03/06/2026 | D16: INW51155 | E16: -13435.5 | F16: -2015.33 | G16: -15450.83
A17: VAN020 | B17: Credit Note : CR10696 | C17: 03/06/2026 | D17: INW50832 | E17: -1201.2 | F17: -180.18 | G17: -1381.38
A18: NMB001 | B18: Credit Note : CR10697 | C18: 04/06/2026 | D18: INW50917 | E18: -3166.6 | F18: -474.99 | G18: -3641.59
A19: CASH | B19: Credit Note : CR10698 | C19: 04/06/2026 | D19: INW51168 | E19: -1756 | F19: -263.4 | G19: -2019.4
... A122: WUN001 | B122: Credit Note : CR10804 | C122: 29/06/2026 | D122: INW52046 | E122: -451.8 | F122: -67.77 | G122: -519.57
A123: GWO001 | B123: Tax Invoice : INW50859 | C123: 01/06/2026 | E123: 47328.3 | F123: 7099.25 | G123: 54427.55
A124: MOO008 | B124: Tax Invoice : INW50936 | C124: 01/06/2026 | E124: 4504 | F124: 675.6 | G124: 5179.6
A125: AARD01 | B125: Tax Invoice : INW50940 | C125: 02/06/2026 | E125: 2539.25 | F125: 380.89 | G125: 2920.14
A126: THE000 | B126: Tax Invoice : INW50984 | C126: 01/06/2026 | E126: 3954.95 | F126: 593.24 | G126: 4548.19
A127: STE018 | B127: Tax Invoice : INW50989 | C127: 01/06/2026 | E127: 1050 | F127: 157.5 | G127: 1207.5
A128: SIT003 | B128: Tax Invoice : INW51003 | C128: 01/06/2026 | E128: 3057.25 | F128: 458.59 | G128: 3515.84
A129: GUI001 | B129: Tax Invoice : INW51004 | C129: 01/06/2026 | E129: 16031.8 | F129: 2404.77 | G129: 18436.57
A130: NKA001 | B130: Tax Invoice : INW51005 | C130: 01/06/2026 | D130: ATT: NKANYISO | E130: 2940 | F130: 441 | G130: 3381
A131: HOP001 | B131: Tax Invoice : INW51006 | C131: 01/06/2026 | D131: PO: 15957 | E131: 24750 | F131: 3712.5 | G131: 28462.5
A132: BAR003 | B132: Tax Invoice : INW51007 | C132: 01/06/2026 | E132: 64195.4 | F132: 9629.31 | G132: 73824.71
A133: BAR003 | B133: Tax Invoice : INW51008 | C133: 01/06/2026 | E133: 6316.7 | F133: 947.51 | G133: 7264.21
A134: BRE003 | B134: Tax Invoice : INW51009 | C134: 01/06/2026 | D134: ATT: MICHELLE/ANGELA | E134: 30375 | F134: 4556.25 | G134: 34931.25
A135: SMI003 | B135: Tax Invoice : INW51010 | C135: 01/06/2026 | D135: ATT:PAM | E135: 700.35 | F135: 105.05 | G135: 805.4
A136: KUR001 | B136: Tax Invoice : INW51011 | C136: 01/06/2026 | E136: 1392.6 | F136: 208.89 | G136: 1601.49
A137: NAN003 | B137: Tax Invoice : INW51012 | C137: 01/06/2026 | E137: 4785.9 | F137: 717.89 | G137: 5503.79
A138: NAUD01 | B138: Tax Invoice : INW51013 | C138: 01/06/2026 | E138: 1542.83 | F138: 231.43 | G138: 1774.26
A139: SEA003 | B139: Tax Invoice : INW51014 | C139: 01/06/2026 | D139: ATT: ADAM | E139: 1668 | F139: 250.2 | G139: 1918.2
A140: MAZ002 | B140: Tax Invoice : INW51015 | C140: 01/06/2026 | E140: 3302.1 | F140: 495.32 | G140: 3797.42
A141: RED001 | B141: Tax Invoice : INW51016 | C141: 01/06/2026 | E141: 40000 | F141: 6000 | G141: 46000
A142: RED001 | B142: Tax Invoice : INW51017 | C142: 01/06/2026 | E142: 8403.75 | F142: 1260.56 | G142: 9664.31
A143: MEY001 | B143: Tax Invoice : INW51018 | C143: 01/06/2026 | D143: PO#MADELEINE | E143: 2861.25 | F143: 429.19 | G143: 3290.44
...

Sheet Stock 

Sheet Per Customer 
A1: AFRICAN GAMESKIN GROUP (PTY) LTD | Prepared by: African Gameskin
A2: Sales by Customer 01/06/2026 to 30/06/2026
A3: Customer Code and Name | B3: Qty | C3: Total Selling
A4: BIR003 - BIRTHMARK INTERIORS | C4: 0
A5: COV021 - COVERFRESH UPHOLSTERY | C5: -128.45
A6: CUR009 - CURLICUE PTY LTD | C6: -32675.7
A7: DIAZ01 - DIAZ DESIGN | C7: -870.05
A8: NMB001 - NMB FURNITURE PTY (LTD) | C8: -1349
A9: NRH01 - NORTH HAMPTON LEATHER | C9: -135.05
A10: OFA004 - OFFROAD ALLEY | C10: 0
A11: OGU001 - OGUN OUTFITTERS | C11: -3160
A12: ORI001 - ORIGIN INTERIORS | C12: 0
A13: SPL001 - SPLITTING IMAGE TAXIDERMY | C13: -493
A14: WUN001 - WUNDERS FINE FURNISHINGS | C14: -15377.3
A15: XIL001 - Xilutsi Trading (Pty) Ltd | C15: 0
A16: INSPIRE RENTALS PTY LTD | B16: 1648.56 | C16: 400521.1 | D16: LM
A17: GH LEATHERS LTD | B17: 1464.08 | C17: 677878.46 | D17: Bianca
A18: JULIANA DESIGNS (PTY) LTD | B18: 1244.83 | C18: 329879.95 | D18: Savannah
A19: COUCH POTATO | B19: 856.94 | C19: 213084.55 | D19: Bianca
A20: INYATHI LOUNGE (PTY) LTD | B20: 834.04 | C20: 202000.95 | D20: Savannah
A21: ALWAYS AROUND (PTY) LTD T/A BEESDAM | B21: 787.17 | C21: 221597.55 | D21: Bianca
A22: LEATHER DIRECT (Pty) Ltd | B22: 722.42 | C22: 181422 | D22: Melani
A23: ROWDY INTERNATIONAL (Pty) Ltd | B23: 707.48 | C23: 215960.95 | D23: Melani
A24: LEATHER DIRECT (Pty) Ltd | B24: 597.6 | C24: 148022.8 | D24: Melani
A25: FF CLOTHING GROUP CC | B25: 583.21 | C25: 232642.6 | D25: Bianca
A26: BOOT & RALLY (PTY) (LTD) | B26: 543.53 | C26: 191245.82 | D26: LM
A27: AFIKA PROMOTIONS | B27: 459.86 | C27: 179935.3 | D27: Melani
... A39: VER001 - VERMONT LEATHER | B39: 249.89 | C39: 89177.9 | D39: LM
A40: CA001 - CASH CUSTOMERS | B40: 244.63 | C40: 88800.75
A41: AUV001 - AUVERGNE | B41: 229.86 | C41: 56315.7 | D41: Jordan
A42: RUS001 - RUSTIC LOVE | B42: 225.95 | C42: 24084.18 | D42: Savannah
A43: STY008 - STYLE 2 FUNK t/a CORPORATE STYLING | B43: 225.94 | C43: 88955.1 | D43: Savannah
A44: EST001 - ESTHE' LEATHER SHOES | B44: 221.76 | C44: 96769.6 | D44: Bianca
A45: CASH - CASH CUSTOMER | B45: 217.84 | C45: 108379.35
A46: PRO015 - PROJECT DYAD | B46: 217.75 | C46: 99439.15 | D46: Bianca
A47: COS001 - TH STEVENS T/A COSY COUCH | B47: 215.62 | C47: 72161.8 | D47: Michelle
A48: GWO001 - G-WORX THREE CC | B48: 210.27 | C48: 84074.85 | D48: Bianca
A49: DON009 - DONKEY LONG TONG (PTY) LTD | B49: 205.2 | C49: 71820 | D49: Bianca
A50: ISL002 - ISLAND HOUSE TRADING 53 (Pty) Ltd t/a | B50: 196.82 | C50: 71271.5 | D50: Melani
A51: KNA002 - KNAP SAK (PTY) LTD | B51: 185.52 | C51: 75574.5 | D51: Savannah
...

Sheet Hannitan
A1: AFRICAN GAMESKIN GROUP (PTY) LTD | Prepared by: African Gameskin
A2: Purchase Items per Supplier : 01/06/2026 to 30/06/2026
B3: Qty | C3: Unit Cost | D3: Total
A4: Supplier : HAN001 - HANNITAN LEATHER CC
A5: Item : AVI001 - AVIATOR WARRIOR | B5: 37.56 | C5: 280 | D5: 10516.8
A6: Item : BWO001 - WOODLAND B PRINT SPICE | B6: 1703.95 | C6: 207 | D6: 352717.65
A7: Item : BWO002 - WOODLAND B PRINT TAN | B7: 2485.45 | C7: 207 | D7: 514488.15
A8: Item : BWO006 - WOODLAND B PRINT GRAPHITE | B8: 681.22 | C8: 207 | D8: 141012.54
A9: Item : CAP002 - CAPE BUFFALO COPPER | B9: 330.06 | C9: 274 | D9: 90436.44
A10: Item : CAP012 - CAPRIVI BRANDY | B10: 568.72 | C10: 187.39035 | D10: 112455.57
A11: Item : CAS007 - CASTROL COCOA MILLED | B11: 1018.77 | C11: 232 | D11: 236354.64
A12: Item : COD001 - CODIAC TAUPE | B12: 739.87 | C12: 207 | D12: 153153.09
A13: Item : DAY002 - DAYTONA ESPRESSO | B13: 407.59 | C13: 292 | D13: 119016.28
A14: Item : DAY011 - DAYTONA TOFFEE | B14: 837.71 | C14: 292 | D14: 244611.32
A15: Item : DIE002 - DIESEL ROSEWOOD | B15: 371.4 | C15: 275 | D15: 102135
A16: Item : DIE004 - DIESEL BLACK | B16: 249.6 | C16: 275 | D16: 68640
... A43: Item : WLS003 - WOODLAND CHARCOAL B | B43: 615.31 | C43: 207 | D43: 127369.17
A44: Total for Supplier : HAN001 - HANNITAN LEATHER CC | B44: =SUM(B5:B43) -> 27484.3 | D44: =SUM(D5:D43) -> 6103468.1
A45: GRAND TOTAL
D46: =+D44/B44 -> 222.07108

Sheet FLW
A1: AFRICAN GAMESKIN GROUP (PTY) LTD | Prepared by: African Gameskin
A2: Purchase Items per Supplier : 01/06/2026 to 30/06/2026
A4: Supplier : TAN001 - FUSION LEATHER WORLD
B5: Qty | C5: Unit Cost | D5: Total
A7: Item : APA001 - APACHE WALNUT | B7: 324.6 | C7: 365 | D7: 118479
A8: Item : ATL007 - ATLANTA TAN | B8: 19.06 | C8: 345 | D8: 6575.7
A9: Item : CAN031 - CANDOR LEMON DROP | B9: 214.7 | C9: 365 | D9: 78365.5
A10: Item : CHI001 - CHICAGO GREEN | B10: 328.45 | C10: 365 | D10: 119884.25
A11: Item : CHI002 - CHICAGO TAN | B11: 304.59 | C11: 364.43465 | D11: 111003.15
A12: Item : COS002 - COSMO DUSTY PINK | B12: 313.03 | C12: 365 | D12: 114255.95
A13: Item : COS003 - COSMO SAGE GREEN | B13: 313.62 | C13: 364.04343 | D13: 114171.3
A14: Item : COS005 - COSMO CHOC | B14: 311.85 | C14: 365 | D14: 113825.25
A15: Item : COW001 - COW SUEDE SPLITS CHOC | B15: 289.2 | C15: 262 | D15: 75770.4
A16: Item : COW002 - COW SUEDE SPLITS BLACK | B16: 314.15 | C16: 262 | D16: 82307.3
A17: Item : COW015 - COW SUEDE CIDER | B17: 202.65 | C17: 252.12607 | D17: 50118
A18: Item : DAL006 - DALLAS CHOC | B18: 23.62 | C18: 345 | D18: 8148.9
... A34: Item : TUS010 - BARCELONA NAVY | B34: 331.92 | C34: 365 | D34: 121150.8
A36: GRAND TOTAL
B37: =SUM(B7:B36) -> 7277.34 | D37: =SUM(D7:D36) -> 2513317.9
D38: =+D37/B37 -> 345.36217

Sheet Customer for the year

Sheet Dashboard Analysis

Sheet Analysis Dashboard
A1: AFRICAN GAMESKIN GROUP - JUNE 2026 DASHBOARD ANALYSIS
A3: KEY PERFORMANCE METRICS | I3: QUICK SUMMARY
A4: Metric | B4: Value | C4: Notes | I4: Total Turnover: | J4: =B5 -> 9605934.8 | L4: Net Profit (YTD): | M4: =B11 -> 1174284.9
A5: Total Turnover | B5: ='Monthly sheet '!D6+'Monthly sheet '!D7 -> 9605934.8 | C5: Local + Exports | I5: Gross Margin: | J5: =B9 -> 0.056603204 | L5: Total Debtors: | M5: =B27 -> 9500331
A6: Local Sales | B6: ='Monthly sheet '!D6 -> 8846029.9 | C6: 92% of turnover | I6: Total Stock: | J6: ='Monthly sheet '!M40 -> 28252762 | L6: Total Creditors: | M6: ='Monthly sheet '!H31 -> 3246489.7
A7: Export Sales | B7: ='Monthly sheet '!D7 -> 759904.9 | C7: 8% of turnover
A8: Gross Profit (June) | B8: ='Monthly sheet '!L21 -> 542952.45
A9: Gross Profit Margin | B9: ='Monthly sheet '!M21 -> 0.056603204 | C9: Below target
A10: Net Profit (June) | B10: ='Monthly sheet '!L24 -> -12544.95 | C10: Loss this month
A11: Net Profit YTD | B11: ='Monthly sheet '!L32 -> 1174284.9 | C11: Positive YTD
A12: YTD Profit Margin | B12: ='Monthly sheet '!M32 -> 0.032801934
A14: SALES BY BRANCH (M2) | F14: Branch Sales Data
A15: Branch | B15: 46174 | C15: 46143 | D15: Change % | F15: Branch | G15: 46174
A16: Durban | B16: ='Monthly sheet '!C18 -> 2362 | C16: ='Monthly sheet '!D18 -> 2702 | D16: =(B16-C16)/C16 -> -0.12583272 | F16: Durban | G16: =B16 -> 2362
A17: JHB | B17: ='Monthly sheet '!C19 -> 9987 | C17: ='Monthly sheet '!D19 -> 9663 | D17: =(B17-C17)/C17 -> 0.03352996 | F17: JHB | G17: =B17 -> 9987
A18: Cape Town | B18: ='Monthly sheet '!C20 -> 15762 | C18: ='Monthly sheet '!D20 -> 14573 | D18: =(B18-C18)/C18 -> 0.08158924 | F18: Cape Town | G18: =B18 -> 15762
A19: TOTAL | B19: =SUM(B16:B18) -> 28111 | C19: =SUM(C16:C18) -> 26938 | D19: =(B19-C19)/C19 -> 0.043544435
A21: DEBTORS AGING ANALYSIS | F21: Debtors Aging Data
A22: Aging Bucket | B22: Amount | C22: % of Total | D22: Risk Level | F22: Aging | G22: Amount
A23: Current | B23: ='Monthly sheet '!H20 -> 5750509.5 | C23: =B23/B27 -> 0.6052957 | D23: Low | F23: Current | G23: =B23 -> 5750509.5
A24: 30 Days | B24: ='Monthly sheet '!H21 -> 2659650.2 | C24: =B24/B27 -> 0.27995342 | D24: Medium | F24: 30 Days | G24: =B24 -> 2659650.2
A25: 60 Days | B25: ='Monthly sheet '!H22 -> 339704.74 | C25: =B25/B27 -> 0.035757148 | D25: High | F25: 60 Days | G25: =B25 -> 339704.74
A26: 90+ Days | B26: ='Monthly sheet '!H23+'Monthly sheet '!H24 -> 750466.57 | C26: =B26/B27 -> 0.078993729 | D26: Critical | F26: 90+ Days | G26: =B26 -> 750466.57
A27: TOTAL | B27: =SUM(B23:B26) -> 9500331 | C27: =SUM(C23:C26) -> 1
A29: STOCK INVENTORY BY LOCATION | F29: Stock Value Data
A30: Location | B30: M2 | C30: Value (R) | D30: % of Total | F30: Location | G30: Value
A31: Cape Town | B31: ='Monthly sheet '!L36 -> 72417 | C31: ='Monthly sheet '!M36 -> 20103816 | D31: =C31/$C$34 -> 0.71156994 | F31: Cape Town | G31: =C31 -> 20103816
A32: JHB | B32: ='Monthly sheet '!L37 -> 26594 | C32: ='Monthly sheet '!M37 -> 6028419 | D32: =C32/$C$34 -> 0.2133745 | F32: JHB | G32: =C32 -> 6028419
A33: Durban | B33: ='Monthly sheet '!L38 -> 3891.47 | C33: ='Monthly sheet '!M38 -> 999058.3 | D33: =C33/$C$34 -> 0.035361438 | F33: Durban | G33: =C33 -> 999058.3
A34: TOTAL | B34: =SUM(B31:B33) -> 102902.47 | C34: ='Monthly sheet '!M40 -> 28252762 | D34: =SUM(D31:D33) -> 0.96030588
A36: TOP 10 CUSTOMERS | F36: Top Customers Data
A37: Rank | B37: Customer | C37: M2 | D37: Value (R) | F37: Customer | G37: Value
A38: 1 | B38: ='Monthly sheet '!B25 -> INSPIRE RENTALS PTY LTD | C38: ='Monthly sheet '!C25 -> 1648.56 | D38: ='Monthly sheet '!D25 -> 400521.1 | F38: INSPIRE RENTALS | G38: =D38 -> 400521.1
A39: 2 | B39: ='Monthly sheet '!B26 -> GH LEATHERS LTD | C39: ='Monthly sheet '!C26 -> 1464.08 | D39: ='Monthly sheet '!D26 -> 677878.46 | F39: GH LEATHERS | G39: =D39 -> 677878.46
A40: 3 | B40: ='Monthly sheet '!B27 -> JULIANA DESIGNS (PTY) LTD | C40: ='Monthly sheet '!C27 -> 1244.83 | D40: ='Monthly sheet '!D27 -> 329879.95 | F40: JULIANA DESIGNS | G40: =D40 -> 329879.95
A41: 4 | B41: ='Monthly sheet '!B28 -> COUCH POTATO | C41: ='Monthly sheet '!C28 -> 856.94 | D41: ='Monthly sheet '!D28 -> 213084.55 | F41: COUCH POTATO | G41: =D41 -> 213084.55
A42: 5 | B42: ='Monthly sheet '!B29 -> INYATHI LOUNGE (PTY) LTD | C42: ='Monthly sheet '!C29 -> 834.04 | D42: ='Monthly sheet '!D29 -> 202000.95 | F42: INYATHI LOUNGE | G42: =D42 -> 202000.95
A43: 6 | B43: ='Monthly sheet '!B30 -> ALWAYS AROUND (PTY) LTD T/A BEESDAM | C43: ='Monthly sheet '!C30 -> 787.17 | D43: ='Monthly sheet '!D30 -> 221597.55 | F43: ALWAYS AROUND | G43: =D43 -> 221597.55
A44: 7 | B44: ='Monthly sheet '!B31 -> LEATHER DIRECT (Pty) Ltd | C44: ='Monthly sheet '!C31 -> 722.42 | D44: ='Monthly sheet '!D31 -> 181422 | F44: LEATHER DIRECT | G44: =D44 -> 181422
A45: 8 | B45: ='Monthly sheet '!B32 -> ROWDY INTERNATIONAL (Pty) Ltd | C45: ='Monthly sheet '!C32 -> 707.48 | D45: ='Monthly sheet '!D32 -> 215960.95 | F45: ROWDY INTL | G45: =D45 -> 215960.95
...
