Workbook

Sheet Monthly sheet 
B1: AFRICAN GAMESKIN GROUP (PTY) LTD
B2: DATE: MAY 2026
B4: SALES | G4: PURCHASES | K4: BANK:
B6: TURNOVER | D6: =+'Income Statement '!C4+'Income Statement '!C5 -> 9194406.5 | G6: HANNITAN - RECEIVED IN MONTH | K6: NEDBANK | L6: =+'Balance sheet '!C38 -> 1922533.5
B7: TURNOVER - EXPORTS | D7: =+'Income Statement '!C6 -> 134522.42 | G7: =+Hannitan!B47 -> 23411.48 | H7: M2 | K7: CFC | L7: =+'Balance sheet '!C39 -> 7298871.1
G8: =+Hannitan!D49 -> 5269998.2 | H8: VALUE EXCL VAT
D9: =SUM(D6:D8) -> 9328928.9 | G9: 270351.36 | H9: 5% DISCOUNT
C10: M2 | G10: =+G8-G9 -> 4999646.9 | H10: TOTAL
B11: LEATHER SOLD: | C11: =+'Sales '!B40+21 -> 26938.21 | D11: =+'Sales '!C40+6789.93 -> 8709915.1 | G11: =+G10/G7 -> 213.55535 | H11: AVERAGE PRICE | K11: LOAN ACCOUNTS
B12: AVERAGE SELLING PRICE: | C12: =+D11/C11 -> 323.32939
B13: LEATHER PURCHASED: | C13: =+G7+G15 -> 29686.34 | D13: =+G10+G16 -> 7174856.5 | G13: FUSION LEATHER - RECEIVED IN MONTH | K13: Spolden Inv | L13: 0
B14: AVERAGE PURCHASE PRICE : | C14: =D13/C13 -> 241.68882 | K14: Hildene Inv | L14: =+'Balance sheet '!C36 -> 1526847.6
G15: =+FLW!B26 -> 6274.86 | H15: M2 | L15: =SUM(L12:L14) -> 1526847.6
B16: SALES BREAKDOWN | G16: =+FLW!D26 -> 2175209.7 | H16: VALUE EXCL VAT
C17: May 2026 | D17: April 2026 | G17: =+G16/G15 -> 346.65469 | H17: AVERAGE PRICE
K18: INCOME STATEMENT MAY 2026
B19: Durban Branch | C19: 2702 | D19: 2416 | G19: DEBTORS AGING AT END OF THE MONTH: | K19: TURNOVER | L19: =+'Income Statement '!D6 -> 9328928.9
B20: JHB Branch | C20: 9663 | D20: 7996 | G20: CURRENT | H20: =+'Debtors '!H177 -> 5628561.9 | K20: COST OF SALES | L20: =+'Income Statement '!D10-600000-85000 -> 7958547.2 | O20: *Took out the sheep lining invoice
B21: Cape Town Branch | C21: 14573 | D21: 13162 | G21: 30DAYS | H21: =+'Debtors '!G177 -> 2778610.7 | K21: GROSS PROFIT | L21: =+L19-L20 -> 1370381.7 | M21: =+L21/L19 -> 0.14689593
B22: Total m2 sold | C22: =SUM(C19:C21) -> 26938 | D22: =SUM(D19:D21) -> 23574 | G22: 60DAYS | H22: =+'Debtors '!F177 -> 1093086.8 | K22: OTHER INCOME | L22: =+'Income Statement '!C13+'Income Statement '!C14 -> 280166.36
G23: 90DAYS | H23: =+'Debtors '!E177 -> 276517.89 | K23: EXPENSES | L23: =+'Income Statement '!D42 -> 953750.41 | M23: =L23/L19 -> 0.10223579
B24: TOP 10 CUSTOMERS | C24: DM2 | D24: VALUE | G24: 120DAYS | H24: =+'Debtors '!D177 -> 200499.67 | K24: NET PROFIT | L24: =L21+L22-L23 -> 696797.61 | M24: =+L24/L19 -> 0.074692134
B25: INS011 - INSPIRE RENTALS PTY LTD | C25: 2096.73 | D25: 507783.65 | H25: =SUM(H20:H24) -> 9977276.9
B26: JUL003 - JULIANA DESIGNS (PTY) LTD | C26: 1132.23 | D26: 300040.95 | K26: INCOME STATEMENT YTD
B27: ALW002 - ALWAYS AROUND (PTY) LTD T/A BEESDAM | C27: 1078.98 | D27: 308631.8 | G27: CREDITORS AGING: | K27: TURNOVER | L27: =+'Year to date'!D6 -> 26210086
B28: BOO002 - BOOT & RALLY (PTY) (LTD) | C28: 967.14 | D28: 336584.75 | G28: CURRENT | H28: =+'Suppliers '!H17 -> 2599600 | K28: COST OF SALES | L28: =+'Year to date'!D10 -> 22855533 | O28: Include the Sheepling
B29: LEA04 - LEATHER DIRECT (Pty) Ltd | C29: 816.29 | D29: 207347.1 | G29: 30DAYS | H29: =+'Suppliers '!G20 -> 0 | K29: GROSS PROFIT | L29: =L27-L28 -> 3354553.2 | M29: =+L29/L27 -> 0.12798711
B30: GAT003 - GATES 2 AFRICA - MIKE | C30: 787.87 | D30: 183644.35 | G30: 60DAYS | H30: 0 | K30: OTHER INCOME | L30: =+'Year to date'!D16 -> 878329.36
B31: INY011 - INYATHI LOUNGE (PTY) LTD | C31: 683.91 | D31: 174273.1 | H31: =SUM(H28:H30) -> 2599600 | K31: EXPENSES | L31: =+'Year to date'!D44 -> 2860231.9 | M31: =L31/L27 -> 0.10912715
B32: ROW002 - ROWDY INTERNATIONAL (Pty) Ltd | C32: 629.04 | D32: 190119.2 | K32: NET PROFIT | L32: =L29+L30-L31 -> 1372650.6 | M32: =+L32/L27 -> 0.052371084
B33: JAL001 - JALAD AFRICA PTY LTD | C33: 574.4 | D33: 211188.95 | G33: STOCK | H33: =+M40 -> 26440667
B34: FAT004 - FF CLOTHING GROUP CC | C34: 510.48 | D34: 211266.6 | G34: DEBTORS | H34: =+H25 -> 9977276.9 | K34: STOCK - May 2026
L35: M2 | M35: VALUE
B36: Top 10 as % of total sales | C36: =+C48 -> 0.34438331 | G36: BANK | H36: =+L7+L6 -> 9221404.6 | K36: Cape Town | L36: =17224+56968+4055 -> 78247 | M36: =6053294+13449228+688425+336375 -> 20527322
B37: CREDIT NOTES: 93 x CREDIT NOTES | C37: 5% of sales | D37: 482483 | G37: CREDITORS | H37: =-H31 -> -2599600 | K37: JHB | L37: =14304+1843+712 -> 16859 | M37: =2978120+619367+106800 -> 3704287 | O37: =+M37/L37 -> 219.72163
K38: Durban | L38: 4205 | M38: 999564.09
K39: Other | M39: =+[1]Gameskin!$F$52 -> 1209494.3
G40: TOTAL CURRENT ASSETS: | H40: =SUM(H33:H39) -> 43039749 | L40: TOTAL STOCK: | M40: =SUM(M36:M39) -> 26440667
D42: =+D37/D9 -> 0.051719014
K44: =+M40-M39 -> 25231173
...

Sheet Balance sheet 
A1: AFRICAN GAMESKIN GROUP (PTY) LTD | Prepared by: African Gameskin
A2: BALANCE SHEET as at 31/05/2026
A4: EQUITY AND LIABILITIES
A5: Capital and Reserves
A7: Share Capital
B8: Members contribution | C8: 100 | D8: 100
A9: Retained Income
B10: Retained Income / (Accumulated Loss) | C10: 33130566
B11: Net Profit/Loss this year | C11: 1372650.6 | D11: 34503217 | E11: 34503317
A13: Minority Interest
A14: Non-current Liabilities
D16: 34503317
A17: Current Liabilities
B18: Nedbank Credit Card | C18: 2851.61
B19: Garage Card - Control Account | C19: 53830.66
B20: Supplier Control Account | C20: 2599600
B21: Provision for Future Expenses | C21: 100754.87
B22: Vat / Tax Control Account | C22: 83312.25 | D22: 2840349.4 | E22: 2840349.4
A23: Total Equity and Liabilities | D23: 37343666
A25: ASSETS
A26: Non-current Assets
A28: Fixed Assets
B29: Motor Vehicles - Net Value | C29: 1438086.1
B30: Computer Equipment - Net Value | C30: 49169.98
B31: Furniture & Fittings - Net value | C31: 16195.62 | D31: 1503451.7 | E31: 1503451.7
A32: Current Assets
B33: Inventory
C34: Inventory | D34: 12760584
B35: Staff Loan | C35: 28882.2
B36: Hildene Investments (Pty) Ltd | C36: 1526847.6
B37: Customer Control Account | C37: 9724487.1
B38: Nedbank Cheque 1036 327663 | C38: 1922533.5
B39: USD Account 7095014132 | C39: 7298871.1
B40: Petty cash | C40: 5331.85
B41: Petty Cash | C41: 42070.69
B42: Sundry Customers | C42: 80463.9
B43: Taxation | C43: 2450142.8 | D43: 35840215 | E43: 35840215
A44: Total Assets | D44: 37343666

Sheet Income Statement 
A1: AFRICAN GAMESKIN GROUP (PTY) LTD | Prepared by: African Gameskin
A2: INCOME STATEMENT : 01/05/2026 to 31/05/2026
A3: SALES
B4: Sales | C4: 9189379
B5: Sales - other | C5: 5027.5
B6: Sales zero rated | C6: 134522.42 | D6: 9328928.9
A7: COST OF SALES
B8: Cost of Sales / Purchases | C8: 8442947.4
B9: Clearing and forwarding | C9: 75013.33
B10: Courier & Postage | C10: 125586.52 | D10: 8643547.2
A11: GROSS PROFIT / (LOSS) | C11: 685381.66
A12: OTHER INCOME
B13: Discount Received for Cash | C13: 270351.36
B14: Interest Received | C14: 9815
B15: Foreign exchange Gain / Loss | C15: -200308.67 | D15: 79857.69
C16: 765239.35
A17: EXPENSES
B18: Advertising & Promotions | C18: 5958.33
B19: Bank Charges | C19: 3078.6
B20: Cleaning | C20: 4336.58
B21: Computer Expenses | C21: 1050.58
B22: Consumables | C22: 9289.67
B23: Consulting Fees | C23: 13086.88
B24: Credit card commission | C24: 15832.6
B25: Discount Allowed for Cash | C25: -37.43
B26: Electricity & Water | C26: 10119.03
B27: Gifts | C27: 9129
B28: Insurance | C28: 29342.51
B29: Interest Paid | C29: 744.13
... B41: Telephone & Fax | C41: 14271.5
B42: Travel & Accommodation | C42: 43304.82 | D42: 953750.41
A43: NET PROFIT / (LOSS) BEFORE TAX | C43: -188511.06
A44: TAX
A45: DIVIDENDS
A46: NET PROFIT / (LOSS) | C46: -188511.06

Sheet Year to date
A1: AFRICAN GAMESKIN GROUP (PTY) LTD | Prepared by: African Gameskin
A2: INCOME STATEMENT : 01/03/2026 to 31/05/2026
A3: SALES
B4: Sales | C4: 25520856
B5: Sales - other | C5: 11098.48
B6: Sales zero rated | C6: 678131.25 | D6: 26210086
A7: COST OF SALES
B8: Cost of Sales / Purchases | C8: 22262560
B9: Clearing and forwarding | C9: 154573.1
B10: Courier & Postage | C10: 438400.12 | D10: 22855533
A11: GROSS PROFIT / (LOSS) | C11: 3354553.2
A12: OTHER INCOME
B13: Discount Received for Cash | C13: 742531.64
B14: Interest Received | C14: 27853.05
B15: Sundry Income | C15: 3293.41
B16: Foreign exchange Gain / Loss | C16: 104651.26 | D16: 878329.36
C17: 4232882.5
A18: EXPENSES
B19: Accounting Fees | C19: 5929
B20: Advertising & Promotions | C20: 15625
B21: Bank Charges | C21: 40819.06
B22: Cleaning | C22: 17020.3
B23: Computer Expenses | C23: 7980.54
B24: Consumables | C24: 52653.17
B25: Consulting Fees | C25: 48961.29
B26: Credit card commission | C26: 36715.24
B27: Discount Allowed for Cash | C27: 346.89
B28: Electricity & Water | C28: 53634.85
B29: Gifts | C29: 9129
B30: Insurance | C30: 84542.48
... B43: Telephone & Fax | C43: 42654.07
B44: Travel & Accommodation | C44: 103910.65 | D44: 2860231.9
A45: NET PROFIT / (LOSS) BEFORE TAX | C45: 1372650.6
A46: TAX
A47: DIVIDENDS
A48: NET PROFIT / (LOSS) | C48: 1372650.6

Sheet Debtors 
A1: AFRICAN GAMESKIN GROUP (PTY) LTD | Prepared by: African Gameskin
A2: Customer Age Analysis for Monthly Customers as at 31/05/2026
A3: Name | D3: 120+ Days | E3: 90 Days | F3: 60 Days | G3: 30 Days | H3: Current | I3: Total Due
A4: AFI001 - AFIKA PROMOTIONS | D4: 0 | E4: 0 | F4: 282273.87 | G4: 7789.76 | H4: 132556.49 | I4: 422620.12
A5: ALE003 - ALEXIOU LEATHER COUCHES | D5: 0 | E5: 38584.63 | F5: 30209 | G5: 12919.91 | H5: 5986.9 | I5: 87700.44
A6: ALW002 - ALWAYS AROUND (PTY) LTD T/A BEESDAM | D6: 0 | E6: 0 | F6: 0 | G6: 0 | H6: 177856.76 | I6: 177856.76
A7: ANG002 - ANGEL FOOTWEAR | D7: 0 | E7: 0 | F7: 30491.74 | G7: 0 | H7: 0 | I7: 30491.74
A8: BAR003 - E BARONOS LEATHER MANUFACTURERS CC | D8: 0 | E8: 0 | F8: 0 | G8: 0 | H8: 3762.92 | I8: 3762.92
A9: BAR004 - BARNO (PTY) LTD | D9: 0 | E9: 0 | F9: 0 | G9: 0 | H9: 30742.84 | I9: 30742.84
A10: BBG001 - BBAGZZ SECURITY | D10: 0 | E10: 0 | F10: 0 | G10: 0 | H10: 3440.81 | I10: 3440.81
A11: BEN005 - BENZE UPHOLSTERY | D11: 0 | E11: 0 | F11: 9822.61 | G11: 21519.84 | H11: 21653.06 | I11: 52995.51
A12: BLU004 - AMBI & CO t/a BLUEBERRY BLUSH | D12: 0 | E12: 0 | F12: 0 | G12: 7145.12 | H12: 3431.95 | I12: 10577.07
A13: BLU011 - BLUE SERIF | D13: 0 | E13: 0 | F13: 0 | G13: 0 | H13: 9693.06 | I13: 9693.06
A14: BOO002 - BOOT & RALLY (PTY) (LTD) | D14: 0 | E14: 0 | F14: 338028.69 | G14: 144497.11 | H14: 387072.48 | I14: 869598.28
A15: BOS010 - BOSVELD CANVAS AND LEATHER | D15: 0 | E15: 0 | F15: 0 | G15: 2306.82 | H15: 29189.84 | I15: 31496.66
... A177: Totals : | D177: 200499.67 | E177: 276517.89 | F177: 1093086.8 | G177: 2778610.7 | H177: 5628561.9 | I177: 9977276.9
A178: PERCENTAGE : | D178: 2.01% | E178: 2.77% | F178: 10.96% | G178: 27.85% | H178: 56.41% | I178: 100.00%
A179: GRAND TOTALS : | I179: 9977276.9

Sheet Suppliers 
A1: AFRICAN GAMESKIN GROUP (PTY) LTD | Prepared by: African Gameskin
A2: Supplier Age Analysis as at 31/05/2026
A3: Name | D3: 120+ Days | E3: 90 Days | F3: 60 Days | G3: 30 Days | H3: Current | I3: Total Due
A4: CEZ001 - CEZ Investements | D4: 0 | E4: 0 | F4: 0 | G4: 0 | H4: -56126.71 | I4: -56126.71
A5: CLO001 - CLOUD LOGISTICS | D5: 0 | E5: 0 | F5: 0 | G5: 0 | H5: 14325.62 | I5: 14325.62
A6: COP001 - COPYWRITE BUSINESS CENTRE CC T/A | D6: 0 | E6: 0 | F6: 0 | G6: 0 | H6: 1886.49 | I6: 1886.49
A7: FRE001 - FREIGHTMORE | D7: 0 | E7: 0 | F7: 0 | G7: 0 | H7: 95021.8 | I7: 95021.8
A8: HAN001 - HANNITAN LEATHER CC | D8: 0 | E8: 0 | F8: 0 | G8: 0 | H8: -12140.26 | I8: -12140.26
A9: OLI001 - OLIVETTI | D9: 0 | E9: 0 | F9: 0 | G9: 0 | H9: 1167.82 | I9: 1167.82
A10: POS001 - POSTNET | D10: 0 | E10: 0 | F10: 0 | G10: 0 | H10: 260 | I10: 260
A11: SIY002 - SIYA BONGA | D11: 0 | E11: 0 | F11: 0 | G11: 0 | H11: 4111 | I11: 4111
A12: TAN001 - FUSION LEATHER WORLD | D12: 0 | E12: 0 | F12: 0 | G12: 0 | H12: 2561612.3 | I12: 2561612.3
A13: THE005 - THE COURIER GUY | D13: 0 | E13: 0 | F13: 0 | G13: 0 | H13: -15537.95 | I13: -15537.95
A14: TSS001 - Technical Support Solutions | D14: 0 | E14: 0 | F14: 0 | G14: 0 | H14: -1999 | I14: -1999
A15: VAN001 - Vandah's Packaging | D15: 0 | E15: 0 | F15: 0 | G15: 0 | H15: 5022.94 | I15: 5022.94
... A17: TOTAL : | D17: 0 | E17: 0 | F17: 0 | G17: 0 | H17: 2599600 | I17: 2599600
A18: PERCENTAGE : | D18: 0.00% | E18: 0.00% | F18: 0.00% | G18: 0.00% | H18: 100.00% | I18: 100.00%
A19: GRAND TOTAL : | I19: 2599600

Sheet Sales 
A1: AFRICAN GAMESKIN GROUP (PTY) LTD | Prepared by: African Gameskin
A2: Sales by Inventory Category 01/05/2026 to 31/05/2026
B3: Qty | C3: Total Selling
A4: Category : 000 - None | B4: 606.41 | C4: 149632.85
A5: Category : 001 - Gazelle | B5: 1248.78 | C5: 452871.05
A6: Category : 002 - Woodland B JHB no print | B6: 1970.16 | C6: 510910.1
A7: Category : 003 - Cape Buffalo | B7: 198.88 | C7: 68042.6
A8: Category : 004 - Classic Collection | B8: 146.98 | C8: 52967.3
A9: Category : 005 - Nappa Collection | B9: 208.36 | C9: 72205.15
A10: Category : 007 - Santos / Sorrento | B10: 1640.65 | C10: 395766.6
A11: Category : 010 - Cow Suede Splits | B11: 1300.78 | C11: 431231.1
A12: Category : 012 - Barcelona | B12: 1413.85 | C12: 596995.75
A13: Category : 013 - Fusion Stock Lot | B13: 683.88 | C13: 234271.99
A14: Category : 015 - Navada | B14: 441.3 | C14: 158402.45
A15: Category : 016 - Nova | B15: 244.75 | C15: 81203.15
... A39: Category : 051 - Antique | B39: 759.14 | C39: 197376.4
A40: GRAND TOTAL | B40: =SUM(B4:B39) -> 26917.21 | C40: =SUM(C4:C39) -> 8703125.2

Sheet Invoices
A1: AFRICAN GAMESKIN GROUP (PTY) LTD | Prepared by: African Gameskin
A2: Sales Journal for period 01/05/2026 to 31/05/2026
A4: Customer | B4: Document | C4: Date | D4: Order | E4: Exclusive | F4: Tax | G4: Inclusive
A5: EVO001 | B5: Credit Note : CR10590 | C5: 04/05/2026 | D5: INW48399 | E5: -984.4 | F5: -147.66 | G5: -1132.06
A6: MER001 | B6: Credit Note : CR10591 | C6: 04/05/2026 | D6: INW49752 | E6: -1209 | F6: -181.35 | G6: -1390.35
A7: FEC001 | B7: Credit Note : CR10592 | C7: 04/05/2026 | D7: INW47017 | E7: -330 | F7: -49.5 | G7: -379.5
A8: ZAB001 | B8: Credit Note : CR10593 | C8: 04/05/2026 | D8: INW49556 | E8: -604.35 | F8: -90.65 | G8: -695
A9: COW003 | B9: Credit Note : CR10594 | C9: 04/05/2026 | D9: 49667 | E9: -1165.25 | F9: -174.79 | G9: -1340.04
A10: MAZ002 | B10: Credit Note : CR10595 | C10: 05/05/2026 | D10: INW49717 | E10: -4555.2 | F10: -683.28 | G10: -5238.48
A11: MAZ002 | B11: Credit Note : CR10596 | C11: 05/05/2026 | D11: INW49732 | E11: -4661.05 | F11: -699.16 | G11: -5360.21
A12: TOP009 | B12: Credit Note : CR10597 | C12: 05/05/2026 | D12: 49563 | E12: -1900 | F12: -285 | G12: -2185
A13: MAZ002 | B13: Credit Note : CR10598 | C13: 06/05/2026 | D13: INW49112 | E13: -1358.1 | F13: -203.72 | G13: -1561.82
A14: PHE001 | B14: Credit Note : CR10599 | C14: 06/05/2026 | D14: VARIOUS | E14: -7420 | F14: -1113 | G14: -8533
A15: CAT007 | B15: Credit Note : CR10600 | C15: 06/05/2026 | D15: INW49637 | E15: -770.8 | F15: -115.62 | G15: -886.42
A16: AFI001 | B16: Credit Note : CR10601 | C16: 07/05/2026 | D16: INW49589 | E16: -2314.85 | F16: -347.23 | G16: -2662.08
A17: PDJ001 | B17: Credit Note : CR10602 | C17: 07/05/2026 | D17: INW49512 | E17: -612 | F17: -91.8 | G17: -703.8
A18: MSJ001 | B18: Credit Note : CR10603 | C18: 07/05/2026 | D18: VARIOUS | E18: -2546 | F18: -381.9 | G18: -2927.9
A19: CAP003 | B19: Credit Note : CR10604 | C19: 08/05/2026 | D19: INW49820 | E19: -11257.35 | F19: -1688.6 | G19: -12945.95
A20: CASH | B20: Credit Note : CR10605 | C20: 08/05/2026 | D20: INW49778 | E20: -1800 | F20: -270 | G20: -2070
A21: CAP003 | B21: Credit Note : CR10606 | C21: 08/05/2026 | D21: INW49973 | E21: -1649.1 | F21: -247.37 | G21: -1896.47
A22: MAG001 | B22: Credit Note : CR10607 | C22: 08/05/2026 | D22: INW48107 | E22: -3987.2 | F22: -598.08 | G22: -4585.28
A23: BLA009 | B23: Credit Note : CR10608 | C23: 08/05/2026 | D23: UNMATCH | E23: -834.3 | F23: -125.15 | G23: -959.45
A24: LON003 | B24: Credit Note : CR10609 | C24: 11/05/2026 | D24: INW49829 | E24: -584.8 | F24: -87.72 | G24: -672.52
... A33: INY011 | B33: Credit Note : CR10618 | C33: 13/05/2026 | D33: INW50155 | E33: -1276.2 | F33: -191.43 | G33: -1467.63
A34: INS011 | B34: Credit Note : CR10619 | C34: 13/05/2026 | D34: 38038 | E34: -1980 | F34: -297 | G34: -2277
A35: SKI003 | B35: Credit Note : CR10620 | C35: 13/05/2026 | D35: UNMATCH | E35: -6825.8 | F35: -1023.88 | G35: -7849.68
A36: VER005 | B36: Credit Note : CR10621 | C36: 13/05/2026 | D36: VARIOUS | E36: -2549.4 | F36: -382.41 | G36: -2931.81
A37: BBG001 | B37: Credit Note : CR10622 | C37: 13/05/2026 | D37: INW50136 | E37: -4126.75 | F37: -619.01 | G37: -4745.76
A38: JOI001 | B38: Credit Note : CR10623 | C38: 13/05/2026 | D38: INW50053 | E38: -4713.25 | F38: -706.99 | G38: -5420.24
A39: POR003 | B39: Credit Note : CR10624 | C39: 14/05/2026 | D39: INW49701 | E39: -18814.95 | F39: -2822.24 | G39: -21637.19
A40: LEA030 | B40: Credit Note : CR10625 | C40: 14/05/2026 | D40: 50004 | E40: -4972.35 | F40: -745.86 | G40: -5718.21
A41: CUR009 | B41: Credit Note : CR10626 | C41: 14/05/2026 | D41: INW48970 | E41: -10633.9 | F41: -1595.09 | G41: -12228.99
A42: CUR009 | B42: Credit Note : CR10627 | C42: 14/05/2026 | D42: INW49348 | E42: -6518.8 | F42: -977.82 | G42: -7496.62
A43: MAZ002 | B43: Credit Note : CR10628 | C43: 14/05/2026 | D43: INW50153 | E43: -1228.5 | F43: -184.28 | G43: -1412.78
A44: MAR050 | B44: Credit Note : CR10629 | C44: 14/05/2026 | D44: INW50333 | E44: -250 | F44: -37.5 | G44: -287.5
A45: GAT003 | B45: Credit Note : CR10630 | C45: 15/05/2026 | D45: INW50293 | E45: -4368.4 | F45: -655.26 | G45: -5023.66
A46: FIO001 | B46: Credit Note : CR10631 | C46: 15/05/2026 | D46: INW50312 | E46: -3216.4 | F46: -482.46 | G46: -3698.86
A47: BAR003 | B47: Credit Note : CR10632 | C47: 15/05/2026 | D47: 50194 | E47: -1209.6 | F47: -181.44 | G47: -1391.04
A48: KER021 | B48: Credit Note : CR10636 | C48: 15/05/2026 | D48: INW49947 | E48: -635.5 | F48: -95.33 | G48: -730.83
A49: BCI001 | B49: Credit Note : CR10637 | C49: 15/05/2026 | D49: 46477 | E49: -2247.2 | F49: -337.09 | G49: -2584.29
...

Sheet Stock 

Sheet Per Customer 
A1: AFRICAN GAMESKIN GROUP (PTY) LTD | Prepared by: African Gameskin
A2: Sales by Customer Code 01/05/2026 to 31/05/2026
B3: Qty | C3: Total Selling
A4: INS011 - INSPIRE RENTALS PTY LTD | B4: 2096.73 | C4: 507783.65
A5: JUL003 - JULIANA DESIGNS (PTY) LTD | B5: 1132.23 | C5: 300040.95
A6: ALW002 - ALWAYS AROUND (PTY) LTD T/A BEESDAM | B6: 1078.98 | C6: 308631.8
A7: BOO002 - BOOT & RALLY (PTY) (LTD) | B7: 967.14 | C7: 336584.75
A8: LEA04 - LEATHER DIRECT (Pty) Ltd | B8: 816.29 | C8: 207347.1
A9: GAT003 - GATES 2 AFRICA - MIKE | B9: 787.87 | C9: 183644.35
A10: INY011 - INYATHI LOUNGE (PTY) LTD | B10: 683.91 | C10: 174273.1
A11: ROW002 - ROWDY INTERNATIONAL (Pty) Ltd | B11: 629.04 | C11: 190119.2
A12: JAL001 - JALAD AFRICA PTY LTD | B12: 574.4 | C12: 211188.95
A13: FAT004 - FF CLOTHING GROUP CC | B13: 510.48 | C13: 211266.6
A14: PDJ001 - PDJ COLLECTIVE (PTY) LTD | B14: 484.73 | C14: 201230.75
A15: CAP003 - CAPE KNIFE CUTTING CC | B15: 471.95 | C15: 164286.35
... A524: GRAND TOTAL | B524: 27579.91 | C524: 9325177.6

Sheet Hannitan
A1: AFRICAN GAMESKIN GROUP (PTY) LTD | Prepared by: African Gameskin
A2: Purchase Items per Supplier : 01/05/2026 to 31/05/2026
A4: Supplier : HAN001 - HANNITAN LEATHER CC | B4: Qty | C4: Unit Cost | D4: Total
A6: Item : ANT002 - ANTIQUE BLACK | B6: 380.41 | C6: 215 | D6: 81788.15
A7: Item : ANT003 - ANTIQUE CHOCOLATE | B7: 623.03 | C7: 215 | D7: 133951.45
A8: Item : ANT004 - ANTIQUE TOBACCO | B8: 357.4 | C8: 215 | D8: 76841
A9: Item : BWO001 - WOODLAND B PRINT SPICE | B9: 2169.89 | C9: 192 | D9: 416618.88
A10: Item : BWO002 - WOODLAND B PRINT TAN | B10: 1388.61 | C10: 192 | D10: 266613.12
A11: Item : BWO003 - WOODLAND B PRINT BROWN | B11: 685.75 | C11: 192 | D11: 131664
A12: Item : CAP003 - CAPE BUFFALO BUTTERSCOTCH | B12: 576.17 | C12: 254 | D12: 146347.18
A13: Item : CAP009 - CAPE BUFFALO RUST | B13: 438.05 | C13: 254 | D13: 111264.7
A14: Item : CAS001 - CASTROL TOFFEE | B14: 643.75 | C14: 278 | D14: 178962.5
A15: Item : CAS003 - CASTROL BLACK | B15: 514.34 | C15: 278 | D15: 142986.52
A16: Item : CAS005 - CASTROL DENIM | B16: 271.04 | C16: 278 | D16: 75349.12
A17: Item : CAS006 - CASTROL TOBACCO | B17: 540.15 | C17: 278 | D17: 150161.7
... A26: Item : MOR004 - MOROCCO STRAW | B26: 345.24 | C26: 270 | D26: 93214.8
A27: Item : NAP010 - BALLET NAPPA SIDES NUDE | B27: 247.37 | C27: 270 | D27: =+B27*C27 -> 66789.9
A28: Item : NAV001 - NAVADA CERISE | B28: 235.16 | C28: 305 | D28: 71723.8
A29: Item : NAV004 - NAVADA BLACK | B29: 314.81 | C29: 305 | D29: 96017.05
A30: Item : NAV006 - NAVADA BROWN | B30: 321.4 | C30: 305 | D30: 98027
A31: Item : NOV003 - NOVA BROWN | B31: 383.36 | C31: 235 | D31: 90089.6
A32: Item : PUL010 - CLASSIC MUSTARD | B32: 355.33 | C32: 260 | D32: 92385.8
A33: Item : SAN006 - SANTOS COTTON WHITE | B33: 414.96 | C33: 201 | D33: 83406.96
A34: Item : SAN010 - SANTOS ICE WHITE | B34: 405.85 | C34: 201 | D34: 81575.85
A35: Item : SAN012 - SANTOS AQUA | B35: 273.29 | C35: 201 | D35: 54931.29
A36: Item : SAN013 - SANTOS BASIL | B36: 271.28 | C36: 201 | D36: 54527.28
A37: Item : SAN015 - SANTOS COFFEE | B37: 260.71 | C37: 201 | D37: 52402.71
A38: Item : SAN016 - SANTOS LIQUORICE | B38: 268.62 | C38: 201 | D38: 53992.62
A39: Item : SAN017 - SANTOS PAPRIKA | B39: 273.12 | C39: 201 | D39: 54897.12
... A44: Item : WLS002 - WOODLAND TAN B | B44: 1373.16 | C44: 192 | D44: 263646.72
A45: Total for Supplier : HAN001 - HANNITAN LEATHER CC | B45: =SUM(B6:B44) -> 26011.48 | D45: =SUM(D6:D44) -> 5646998.2
A46: GRAND TOTAL
B47: =+B45-2600 -> 23411.48 | D47: =+D45/B45 -> 217.09638
D49: =+D45- (2600*145) -> 5269998.2

Sheet FLW
A1: AFRICAN GAMESKIN GROUP (PTY) LTD | Prepared by: African Gameskin
A2: Purchase Items per Supplier : 01/05/2026 to 31/05/2026
B3: Qty | C3: Unit Cost | D3: Total
A4: Supplier : TAN001 - FUSION LEATHER WORLD
A5: Item : CAN032 - CANDOR BONE WHITE | B5: 257.78 | C5: 348.33333 | D5: 81200.7
A6: Item : COW001 - COW SUEDE SPLITS CHOC | B6: 281.93 | C6: 262 | D6: 73865.66
A7: Item : COW010 - COW SUEDE SPLITS DUSTY BLUE | B7: 213.65 | C7: 262 | D7: 55976.3
A8: Item : COW011 - COW SUEDE TAN SUB: 1.6/1.8mm | B8: 206.4 | C8: 262 | D8: 54076.8
A9: Item : ECO008 - ECO TAN | B9: 299.94 | C9: 363.25165 | D9: 108953.7
A10: Item : HAV001 - HAVANA PLUS WALNUT | B10: 306.92 | C10: 364.5709 | D10: 111894.1
A11: Item : HAV004 - HAVANA PLUS PLUS WALNUT | B11: 289.39 | C11: 364.76502 | D11: 105423.35
A12: Item : PIT001 - PITSTOP CIGAR | B12: 294.16 | C12: 365 | D12: 107368.4
A13: Item : ROS002 - ROSY NAPPA BLACK | B13: 327.96 | C13: 330 | D13: 108226.8
A14: Item : SAL007 - SALVADOR DARK CHOC | B14: 312.88 | C14: 365 | D14: 114201.2
A15: Item : TEX004 - TEXAS HAZELNUT | B15: 319.04 | C15: 365 | D15: 116449.6
A16: Item : TEX005 - TEXAS BLACK | B16: 320.56 | C16: 365 | D16: 117004.4
... A24: Item : VEG006 - VEG NATURAL SIDES 2.0/2.2mm | B24: 325.84 | C24: 314.2303 | D24: 102388.8
A25: Total for Supplier : TAN001 - FUSION LEATHER WORLD
A26: GRAND TOTAL | B26: =SUM(B5:B25) -> 6274.86 | D26: =SUM(D5:D25) -> 2175209.7
D28: =+D26/B26 -> 346.65469

Sheet Customer for the year
I2: Average Selling Price:
I4: April 2025: R312
I5: April 2026: R324
J7: Ave Selling Price / m2 | K7: Ave Purchase Price / m2 | L7: Gross Profit / m2 | M7: m2 sold
I8: 45748 | J8: 312 | K8: 228 | L8: =+J8-K8 -> 84 | M8: =+'[3]Monthly sheet '!$C$11 -> 24324.74
I9: 46113 | J9: 324 | K9: 238 | L9: =+J9-K9 -> 86 | M9: =+'Monthly sheet '!C11 -> 26938.21
